Workbook

Sheet 電機廠報告與驗收規範
B1: 綠底為電機規格 | D1: 黃底為量測結果 | Y1: 紅底為驗收標準
B2: 馬達型號 | F2: 馬達型態(感應/永磁) | H2: 額定電壓*(Vrms) | J2: 額定轉速(rpm) | L2: 額定功率(kW) | N2: 額定轉矩(Nm) | P2: 額定電流(Arms) | R2: 額定頻率(Hz) | T2: 電機耐壓** (Vrms) | V2: Max acc.運行秒數(s) | Y2: S2 目標轉速(rpm)(註1) | AA2: S3/S6 目標轉速(rpm)(註1) | AC2: S3/S6 目標負荷時間率(%) | AE2: Max acc. 目標轉速(rpm)
B3: α12L (SIMW-132N-15-08) | F3: 感應 | H3: 260 | J3: 1500 | L3: 11 | N3: 70 | P3: 32.3 | R3: 51.5 | T3: 380 | V3: =AB84 -> 20 | Y3: 1500 | AA3: 1500 | AC3: 15
F4: 轉子慣量(kgm2) | H4: 最大轉速(rpm) | J4: 最大轉矩Mmax(Nm) | L4: 最大電流Imax(Arms) | N4: 激磁電流(Arms) | P4: 電機極數(Poles) | R4: 150%過負載運轉時間(s) | T4: 冷卻規格(kw / BTU) | V4: Max acc.最大轉矩(Nm) | W4: Max acc.最大電流(Arms) | Y4: S2 目標扭矩(Nm) | AA4: S3/S6 目標扭矩(Nm) | AE4: Max acc. 目標扭矩(Nm)
F5: 0.07697 | H5: 8000 | J5: =MAX(N56:N58) -> 140 | L5: =MAX((R56+S56+T56)/3,(R57+S57+T57)/3,(R58+S58+T58)/3) -> 67.8 | N5: 14.35 | P5: 4 | R5: =J53 -> 1800 | T5: =ROUND(Y29,2)&" / "&ROUND(Z29,0) -> 1.5 / 5130 | V5: =N84 -> NA | W5: =AVERAGE(U84:W84) -> 113.76667 | Y5: 105 | AA5: 140
B7: 測試類型 | C7: 步驟 | D7: 測試項目 | F7: 測試方式 | J7: 測試結果 | AC7: 合格標準 (請電機廠提供標準) | AE7: 備註/說明 (例：測試方式、量測儀器…等)
B8: 半成品 | C8: 1 | D8: 動平衡檢驗 | F8: 紀錄轉子動平衡檢測數值 | AC8: 0.8mm/sec
B9: 半成品 | C9: 2 | D9: 匝間絕緣測試 | F9: 使用耐壓測試儀，測試各相線圈間衰減震盪波型差異。 | J9: 測試電壓(V) | L9: AC1000 | M9: AC1000 | N9: AC1000 | AC9: ≦10%
J10: 測試時間(s) | L10: 60 | M10: 60 | N10: 60
J11: 波型差異(%) | L11: U - V | M11: V - W | N11: U - W
L12: 1.2 | M12: 8.6 | N12: 8.2
B13: 上電前 | C13: 3 | D13: 繞組電阻測試 | F13: 使用低阻計量測U-V，V-W，U-W線電阻 | J13: 參數來源 | L13: Ru-v(Ω) | M13: Rv-w(Ω) | N13: Ru-w(Ω) | O13: Ravg (Ω) | AC13: ±3%
J14: 量測數值 | L14: 0.27 | M14: 0.27 | N14: 0.27 | O14: 0.27
J15: 規格書(設計值) | L15: 0.27 | M15: 0.27 | N15: 0.27 | O15: 0.27
J16: 誤差 | L16: =(L14-O14)/O14 -> 0 | M16: =(M14-O14)/O14 -> 0 | N16: =(N14-O14)/O14 -> 0 | O16: =(O14-O15)/O15 -> 0
B17: 上電前 | C17: 4 | D17: 繞組絕緣阻抗測試 | F17: 使用耐壓測試儀，同時測試三相繞組對殼之間絕緣阻抗 | J17: 測試電壓(V) | L17: DC500V | AC17: ≧100MΩ
J18: 測試時間(s) | L18: 60
J19: 三相繞組對殼之間絕緣阻抗(Ohm) | L19: 1512M
B20: 上電前 | C20: 5 | D20: 繞組耐壓測試 | F20: 使用耐壓測試儀，同時測試三相繞組對殼之間漏電流 | J20: 測試電壓(V) | L20: AC1800 | AC20: ≦15mA
J21: 測試時間(s) | L21: 60
J22: 三相繞組與機殼間漏電流(mA) | L22: 5.1
B23: 上電前 | C23: 6 | D23: 外型圖檢驗 | F23: 確認電機安裝外型尺寸與外型圖相符 | J23: 是
B24: 上電前 | C24: 7 | D24: 軸偏擺檢驗 | F24: 以千分表量測電機軸心末端偏擺量 | J24: 0.01 | AC24: ≦0.01mm
B25: 上電前 | C25: 8 | D25: 接線方式 | F25: 紀錄三角接或是Y接，確認測試時電機接線方式 | J25: 接線方式 | L25: Y
B26: 上電後 | C26: 9 | D26: 溫升測試 (此項參數已連結，由連結表格輸入) | F26: 測試項目一 : 空載測試。 測試項目二 : 額定測試。(S1 連續工作制) | J26: 電機運轉操作型態 | L26: 測試條件 (空/水/油冷) | M26: 實驗環溫 (°C) | N26: 線圈溫度 (°C) | O26: 前軸承溫度 (°C) | P26: 後軸承溫度 (°C) | Q26: 編碼器溫度 (°C) | R26: 外殼溫度 (°C) | S26: 達穩態或110°C的時間 (min) | U26: 冷卻液設定流量 (L/min) | V26: 冷卻液實際流量 (L/min) | W26: 冷卻液進口溫度 (°C) | X26: 冷卻液出口溫度 (°C) | Y26: 冷卻能力 (kw) | Z26: 冷卻能力 (BTU/h)
J27: 空載額定轉速操作 | L27: =馬達溫升實驗表格!C15 -> 水 | M27: =馬達溫升實驗表格!D15 -> 29.7 | N27: =馬達溫升實驗表格!E15 -> 36.1 | O27: =馬達溫升實驗表格!F15 -> 34.6 | P27: =馬達溫升實驗表格!G15 -> 32.1 | Q27: =馬達溫升實驗表格!H15 -> 29.6 | R27: =馬達溫升實驗表格!I15 -> 28.9 | S27: =馬達溫升實驗表格!J15 -> 150 | U27: =馬達溫升實驗表格!K15 -> 4 | V27: =馬達溫升實驗表格!L15 -> 10 | W27: =馬達溫升實驗表格!M15 -> 25.6 | X27: =馬達溫升實驗表格!N15 -> 27.2 | Y27: =馬達溫升實驗表格!O15 -> 1.0934187 | Z27: =馬達溫升實驗表格!P15 -> 3730.7445
J28: 空載最大轉速操作 | M28: =馬達溫升實驗表格!D16 -> 29.9 | N28: =馬達溫升實驗表格!E16 -> 39.2 | O28: =馬達溫升實驗表格!F16 -> 67 | P28: =馬達溫升實驗表格!G16 -> 46 | Q28: =馬達溫升實驗表格!H16 -> 38.2 | R28: =馬達溫升實驗表格!I16 -> 31.7 | S28: =馬達溫升實驗表格!J16 -> 150 | U28: =馬達溫升實驗表格!K16 -> 4 | V28: =馬達溫升實驗表格!L16 -> 10 | W28: =馬達溫升實驗表格!M16 -> 26.4 | X28: =馬達溫升實驗表格!N16 -> 27.9 | Y28: =馬達溫升實驗表格!O16 -> 1.02508 | Z28: =馬達溫升實驗表格!P16 -> 3497.573
J29: 連續工作制(S1) (額定轉速) | M29: =馬達溫升實驗表格!D17 -> 35 | N29: =馬達溫升實驗表格!E17 -> 62.3 | O29: =馬達溫升實驗表格!F17 -> 41.1 | P29: =馬達溫升實驗表格!G17 -> 40.8 | Q29: =馬達溫升實驗表格!H17 -> 39.5 | R29: =馬達溫升實驗表格!I17 -> 35.2 | S29: =馬達溫升實驗表格!J17 -> 180 | U29: =馬達溫升實驗表格!K17 -> 10 | V29: =馬達溫升實驗表格!L17 -> 10 | W29: =馬達溫升實驗表格!M17 -> 25.3 | X29: =馬達溫升實驗表格!N17 -> 27.5 | Y29: =馬達溫升實驗表格!O17 -> 1.5034507 | Z29: =馬達溫升實驗表格!P17 -> 5129.7737
J30: 1. 溫度量測點 : 定子線圈繞阻、編碼器、外殼表面、前後軸承溫度、冷卻液進出口水溫(電機側) 2. 測試條件若為空冷，則冷卻液流量後的數據免填 3. 實際冷卻流量請填入量測到之數值 4. 冷卻液進口溫度範圍請控制在25~30°C
B31: 上電後 | C31: 10 | D31: S1 100%負載連續使用測試 | F31: 電機於溫升測試達熱穩態後後進行T-N與P-N曲線測試。 參考以下紀錄負載T-N與P-N曲線測試數據 初始轉速: 50%額定轉速測試 轉速間隔: 50%額定轉速 最終轉速:電機最高轉速規格 最終扭力: 該轉速對應T-N曲線規格最大扭力 以"量測轉速"等於"目標轉速"的情況下進行測試，加大扭力會增加滑差、使"量測轉速"降低，請再提高轉速命令(同步頻率)，使"量測轉速"等於"目標轉速"，再紀錄測試結果 如果因實驗設備限制，請註明可以實測的轉矩與速度的範圍；並且提供建議的測試操作點。(請電機廠備註使用的驅動器) 無法提供的數據請備註原因, 並填上N/A 其餘細節參考表格下方備註 | J31: 目標轉速(%) (註2) | K31: 目標轉速(RPM) | L31: 轉矩設定(%) | M31: 轉矩設定(Nm)(註1) | N31: 量測轉速(RPM) | O31: 同步頻率(Hz) | P31: 量測轉矩(Nm) | Q31: 線電壓1 (Vrms) | R31: 線電壓2 (Vrms) | S31: 線電壓3 (Vrms) | T31: 線電流1 (Arms) | U31: 線電流2 (Arms) | V31: 線電流3 (Arms) | W31: 電機輸入功率(kW) | X31: 電機輸出功率(kW) | Y31: 功因 | Z31: 效率(%)
J33: 0.5 | K33: =J33*$J$3 -> 750 | L33: 1 | M33: =L33*$N$3 -> 70 | N33: 749 | O33: 26.4 | P33: 70.14 | Q33: 134.1 | R33: 134.2 | S33: 134..1 | T33: 32.2 | U33: 32.3 | V33: 32.1 | W33: 6.75 | X33: 5.5 | Y33: 0.89 | Z33: 81.6
J34: 1 | K34: =J34*$J$3 -> 1500 | L34: 1 | M34: =L34*$N$3 -> 70 | N34: 1502 | O34: 51.3 | P34: 69.36 | Q34: 257.5 | R34: 257.5 | S34: 257.7 | T34: 32.3 | U34: 32.1 | V34: 32.2 | W34: 12.53 | X34: 10.91 | Y34: 0.87 | Z34: 87
J35: 1.5 | K35: =J35*$J$3 -> 2250 | L35: =IF($M35 = $N$3/$J35,1/$J35,M35/$N$3) -> 0.66666667 | M35: =$N$3/$J35 -> 46.666667
J36: 2 | K36: =J36*$J$3 -> 3000 | L36: =IF($M36 = $N$3/$J36,1/$J36,M36/$N$3) -> 0.5 | M36: =$N$3/$J36 -> 35
J37: 2.5 | K37: =J37*$J$3 -> 3750 | L37: =IF($M37 = $N$3/$J37,1/$J37,M37/$N$3) -> 0.4 | M37: =$N$3/$J37 -> 28
J38: 3 | K38: =J38*$J$3 -> 4500 | L38: =IF($M38 = $N$3/$J38,1/$J38,M38/$N$3) -> 0.33333333 | M38: =$N$3/$J38 -> 23.333333
J39: 3.5 | K39: =J39*$J$3 -> 5250 | L39: =IF($M39 = $N$3/$J39,1/$J39,M39/$N$3) -> 0.28571429 | M39: =$N$3/$J39 -> 20
J40: 4 | K40: =J40*$J$3 -> 6000 | L40: =IF($M40 = $N$3/$J40,1/$J40,M40/$N$3) -> 0.25 | M40: =$N$3/$J40 -> 17.5
J41: 最高轉速 | K41: =H5 -> 8000 | L41: =IF($M41 = $N$3/($H$5/$J$3),1/($H$5/$J$3),$M40/$N$3) -> 0.1875 | M41: =$N$3/($H$5/$J3) -> 13.125
B42: 上電後 | C42: 11 | D42: S2 短時間使用過負載測試 [ S2 N sec. ] | F42: 電機於一定負荷下,，短時間連續運轉 N sec (註5) a .負載率 : 於S2目標轉速下須為S2目標扭矩。額定轉速後定功率區轉矩設定依照推算的設定。 b. 運轉時間 : 在一定負載下電機由啟動運轉未達熱平衡之時間 (註2)。 (啟動溫度需與測試環境差在2°C之內)。 參考以下紀錄負載T-N與P-N曲線測試數據 初始轉速: S2目標轉速/50%額定轉速測試 (S2目標轉速≦額定轉速) 轉速間隔: 50%額定轉速(100%目標轉速以上) 最終轉速:電機最高轉速規格 最終扭力: 該轉速對應T-N曲線規格最大扭力 無法提供的數據請備註原因， 並填上N/A 其餘細節參考表格下方備註 | J42: 目標轉速(%) (註3) | K42: 目標轉速(RPM) | L42: 轉矩設定(%) | M42: 轉矩設定(Nm) (註1) | N42: 量測轉速(RPM) | O42: 同步頻率(Hz) | P42: 量測轉矩(Nm) | Q42: 線電壓1 (Vrms) | R42: 線電壓2 (Vrms) | S42: 線電壓3 (Vrms) | T42: 線電流1 (Arms) | U42: 線電流2 (Arms) | V42: 線電流3 (Arms) | W42: 電機輸入功率(kW) | X42: 電機輸出功率(kW) | Y42: 功因 | Z42: 效率(%)
...

Sheet 馬達溫升實驗表格
B2: 馬達型號 | D2: 馬達型態 | E2: 電壓(Vrms) | F2: 額定轉速(rpm) | G2: 額定功率(kW) | H2: 額定扭矩(Nm) | I2: 額定電流(A) | J2: 最大轉速(rpm) | K2: 弱磁轉速(rpm) | L2: 最大扭矩Mmax(Nm) | M2: 最大電流Imax(A) | N2: 啟動扭矩Mo(Nm) | O2: 啟動電流Io(A)
B3: =電機廠報告與驗收規範!B3 -> α12L (SIMW-132N-15-08) | D3: =電機廠報告與驗收規範!F3 -> 感應 | E3: =電機廠報告與驗收規範!H3 -> 260 | F3: =電機廠報告與驗收規範!J3 -> 1500 | G3: =電機廠報告與驗收規範!L3 -> 11 | H3: =電機廠報告與驗收規範!N3 -> 70 | I3: =電機廠報告與驗收規範!P3 -> 32.3 | J3: =電機廠報告與驗收規範!H5 -> 8000 | K3: =電機廠報告與驗收規範!#REF! -> #REF! | L3: =電機廠報告與驗收規範!J5 -> 140 | M3: =電機廠報告與驗收規範!L5 -> 67.8 | N3: =電機廠報告與驗收規範!#REF! -> #REF! | O3: =電機廠報告與驗收規範!#REF! -> #REF!
B6: 冷卻液種類 | C6: 密度(g/cm3) | D6: 比熱(J/gK) | E6: 黏度(mm2/s)
B7: 水 | C7: 0.98 | D7: 4.184 | E7: 0.893
B8: 備註: 1. 若種類為水，則請填入: 密度= 0.98、比熱 = 4.184、黏度 = 0.893 2. 若種類為油或其他冷卻液，請填入對應規格
B14: 電機運轉操作型態 | C14: 測試條件(空/水/油冷) | D14: 實驗環溫(°C) | E14: 線圈溫度(°C) | F14: 前軸承溫度(°C) | G14: 後軸承溫度(°C) | H14: 編碼器溫度(°C) | I14: 外殼溫度(°C) | J14: 達穩態或110°C的時間(min) | K14: 冷卻液流量(L/min) | L14: 冷卻液實際流量(L/min) | M14: 冷卻液進口溫度(°C) | N14: 冷卻液出口溫度(°C) | O14: 冷卻能力(kw) | P14: 冷卻能力(BTU/h)
B15: 空載額定轉速操作 | C15: 水 | D15: 29.7 | E15: 36.1 | F15: 34.6 | G15: 32.1 | H15: 29.6 | I15: 28.9 | J15: 150 | K15: 4 | L15: 10 | M15: 25.6 | N15: 27.2 | O15: =((L15*0.001/60)*($C$7*1000)*$D$7*(N15-M15)) -> 1.0934187 | P15: =O15*3412 -> 3730.7445
B16: 空載最大轉速操作 | D16: 29.9 | E16: 39.2 | F16: 67 | G16: 46 | H16: 38.2 | I16: 31.7 | J16: 150 | K16: 4 | L16: 10 | M16: 26.4 | N16: 27.9 | O16: =((L16*0.001/60)*($C$7*1000)*$D$7*(N16-M16)) -> 1.02508 | P16: =O16*3412 -> 3497.573
B17: 連續工作制(S1) (額定轉速) | D17: 35 | E17: 62.3 | F17: 41.1 | G17: 40.8 | H17: 39.5 | I17: 35.2 | J17: 180 | K17: 10 | L17: 10 | M17: 25.3 | N17: 27.5 | O17: =((L17*0.001/60)*($C$7*1000)*$D$7*(N17-M17)) -> 1.5034507 | P17: =O17*3412 -> 5129.7737
K18: 7.5 | O18: =((L18*0.001/60)*($C$7*1000)*$D$7*(N18-M18)) -> 0 | P18: =O18*3412 -> 0
K19: 4 | O19: =((L19*0.001/60)*($C$7*1000)*$D$7*(N19-M19)) -> 0 | P19: =O19*3412 -> 0
B20: 連續工作制(S1) (1500RPM) | K20: 4 | O20: =((L20*0.001/60)*($C$7*1000)*$D$7*(N20-M20)) -> 0 | P20: =O20*3412 -> 0
B21: （擴充欄位） | K21: 4 | O21: =((L21*0.001/60)*($C$7*1000)*$D$7*(N21-M21)) -> 0 | P21: =O21*3412 -> 0
B22: 備註: 1. 溫度量測點 : 定子線圈繞阻、編碼器、外殼表面、前後軸承溫度、冷卻液進出口水溫(電機側) 2. 測試條件若為空冷，則從冷卻液流量後的數據免填寫，且各測試條件數據填寫一列即可 3. 實際冷卻流量請填入量測到之數值 4. 冷卻液進口溫度範圍請控制在25~30°C
B30: 實驗環溫要求:-15°C to 40°C | I30: 一、測試項目一：空載測試。 -空載額定轉速操作：零轉矩、額定轉速下運行 -空載最大轉速操作：零轉矩、最大轉速下運行 測試步驟： 1. 冷卻液按照表格內設定流量（若冷卻方式為水冷需調整） 2. 30min內溫度差小於1度C則判斷達到穩定 紀錄 ： 達穩定後記錄實際冷卻液流量、電機進出口溫度、穩定溫度數值、達穩態或110℃的時間。 二、測試項目二 ：額定測試（S1 連續工作制） -連續工作制(S1) (額定轉速)：額定轉矩、額定轉速下運行 -連續工作制(S1) (1500RPM)：額定轉矩、1500rpm下運行 測試步驟： 1.冷卻液按照表格內設定流量（若冷卻方式為水冷需調整） 2.，4HR內溫度差小於1度C則判斷達到穩定 紀錄 ： 達穩定後記錄實際冷卻液流量、電機進出口溫度、穩定溫度數值、達穩態或110℃的時間。 三、於報告與驗收規範表內備註欄位填寫： 1.量測方式 2.量測儀器 3.驅動器廠牌、型號、新代驅動器另紀錄版本與參數 4.水冷/油冷機型號 所有量測點溫升限制 ：依循新代電機溫昇標準
B31: 海拔高度(m) | D31: 環境溫度(°C)
D32: 40 | E32: 45 | F32: 50 | G32: 55
B33: 1000 | D33: 1 | E33: 0.96 | F33: 0.92 | G33: 0.87
B34: 1500 | D34: 0.97 | E34: 0.93 | F34: 0.89 | G34: 0.84
B35: 2000 | D35: 0.94 | E35: 0.9 | F35: 0.86 | G35: 0.82
B36: 2500 | D36: 0.9 | E36: 0.86 | F36: 0.83 | G36: 0.78
B37: 3000 | D37: 0.86 | E37: 0.82 | F37: 0.79 | G37: 0.75
B38: 3500 | D38: 0.82 | E38: 0.79 | F38: 0.75 | G38: 0.71
B39: 4000 | D39: 0.77 | E39: 0.74 | F39: 0.71 | G39: 0.67
D42: 連續工作制(S1)
B43: 超載比率 | D43: 1

Sheet 新代驅動器參數
C1: Version | D1: 1.15
C2: 此頁面為自動計算請勿修改
D3: 轉換新代驅動器參數
B4: Index | C4: Pn | D4: 描述 | E4: 數值 | F4: 單位
B5: =HEX2DEC(C5) -> 1792 | C5: 700 | D5: 馬達型態 | E5: 2 | F5: --
B6: =HEX2DEC(C6) -> 1793 | C6: 701 | D6: 馬達極數 | E6: =電機廠報告與驗收規範!P5 -> 4 | F6: --
B7: =HEX2DEC(C7) -> 1800 | C7: 708 | D7: 馬達額定扭矩 | E7: =電機廠報告與驗收規範!N3*10 -> 700 | F7: 0.1N-m
B8: =HEX2DEC(C8) -> 1802 | C8: 70A | D8: 馬達最大扭矩 | E8: =MAX(電機廠報告與驗收規範!J5/電機廠報告與驗收規範!N3,電機廠報告與驗收規範!L5/電機廠報告與驗收規範!P3)*1000 -> 2099.0712 | F8: 0.1%
B9: =HEX2DEC(C9) -> 1804 | C9: 70C | D9: 馬達額定轉速 | E9: =電機廠報告與驗收規範!J3 -> 1500 | F9: rev/min
B10: =HEX2DEC(C10) -> 1806 | C10: 70E | D10: 馬達最高轉速 | E10: =電機廠報告與驗收規範!H5 -> 8000 | F10: rev/min
B11: =HEX2DEC(C11) -> 1808 | C11: 710 | D11: 馬達額定電流 | E11: =電機廠報告與驗收規範!P3*10 -> 323 | F11: 0.1Arms
B12: =HEX2DEC(C12) -> 1810 | C12: 712 | D12: 感應電機額定電壓 | E12: =電機廠報告與驗收規範!H3*10 -> 2600 | F12: 0.1Vrms
B13: =HEX2DEC(C13) -> 1812 | C13: 714 | D13: 電機激磁軸感抗 | E13: =(D25+D26)*1000 -> 31959.549 | F13: 0.001mH | G13: Lm+L1
B14: =HEX2DEC(C14) -> 1814 | C14: 716 | D14: 電機扭力軸感抗 | E14: =(D25+D26)*1000 -> 31959.549 | F14: 0.001mH | G14: Lm+L1
B15: =HEX2DEC(C15) -> 1816 | C15: 718 | D15: 電機阻抗 | E15: =D28*1000 -> 135 | F15: 0.001Ohm | G15: R1
B16: =HEX2DEC(C16) -> 1818 | C16: 71A | D16: 感應電機漏感比 | E16: =(1-D25^2/(D25+D26)/(D25+D27))*1000 -> 64.785174 | F16: 0.1% | G16: 1-Lm^2/(Lm+L1)/(Lm+L2)
B17: =HEX2DEC(C17) -> 1820 | C17: 71C | D17: 感應電機激磁電流 | E17: =SQRT( (AVERAGE(電機廠報告與驗收規範!Q34:S34) / SQRT(3))^2 + AVERAGE(電機廠報告與驗收規範!T34:'電機廠報告與驗收規範'!V34)^2*(電機廠報告與驗收規範!R70^2+電機廠報告與驗收規範!R72^2) - 2 * AVERAGE(電機廠報告與驗收規範!Q34:S34) / SQRT(3) * AVERAGE(電機廠報告與驗收規範!T34:'電機廠報告與驗收規範'!V34)*SQRT(電機廠報告與驗收規範!R70^2+電機廠報告與驗收規範!R72^2) * COS( PI()/2 - ACOS(電機廠報告與驗收規範!Y34) - ATAN(電機廠報告與驗收規範!R70/電機廠報告與驗收規範!R72) ) ) / 電機廠報告與驗收規範!R74/(E11/10)*1000 -> 432.5043 | F17: 0.1% | G17: 激磁電流/額定電流
B18: =HEX2DEC(C18) -> 1822 | C18: 71E | D18: 感應電機轉子時間常數 | E18: =(電機廠報告與驗收規範!L76^2-(E11*0.1*E17*0.001)^2)^(1/2)/(E11*0.1*E17*0.001)/(電機廠報告與驗收規範!L79/100*電機廠報告與驗收規範!L77*2*PI()/60)/(電機廠報告與驗收規範!P5/2)*10000 -> 2679.9136 | F18: 0.1ms | G18: ((額定電流^2-激磁電流^2)^1/2)/slip/激磁電流/(pole/2)
B19: =HEX2DEC(C19) -> 1824 | C19: 720 | D19: 轉子慣量 | E19: =電機廠報告與驗收規範!F5*10000000 -> 769700 | F19: g-cm2
B20: =HEX2DEC(C20) -> 1832 | C20: 728 | D20: 電流迴路積分時間常數 | E20: =E16*E13/E15*0.1 -> 1533.7074 | F20: 0.01ms | G20: sigma*Ls/R1
B21: =HEX2DEC(C21) -> 1834 | C21: 72A | D21: 過負載150%運轉時間 | E21: =電機廠報告與驗收規範!R5 -> 1800 | F21: s
C22: 730 | D22: 智慧溫控最大扭矩 | E22: =IF(電機廠報告與驗收規範!N84="",1000,1000*MAX(電機廠報告與驗收規範!V5/電機廠報告與驗收規範!N3,電機廠報告與驗收規範!W5/電機廠報告與驗收規範!P3)) -> #VALUE! | F22: 0.1%
C23: 731 | D23: 開啟智慧溫控功能 | E23: =IF(電機廠報告與驗收規範!N84="",0,1) -> 1 | F23: --
C25: Lm | D25: =電機廠報告與驗收規範!R74/(2*PI()*電機廠報告與驗收規範!R3) *1000 -> 30.906963 | E25: mH
C26: L1 | D26: =電機廠報告與驗收規範!R72/(2*PI()*電機廠報告與驗收規範!R3) *1000 -> 1.0525859 | E26: mH
C27: L2 | D27: =電機廠報告與驗收規範!R73/(2*PI()*電機廠報告與驗收規範!R3) *1000 -> 1.0525859 | E27: mH
C28: R1 | D28: =電機廠報告與驗收規範!R70 -> 0.135 | E28: ohm
C29: R2 | D29: =電機廠報告與驗收規範!R71 -> 0.1693 | E29: ohm

Sheet 馬達特性曲線
A3: 特性曲線圖，須調整部分 : 1. 座標軸選項 → 水平(值)軸 →範圍 : a. 最小值 : 0 。 b. 最大值 : 電機最高轉速 。 c. 單位 (主要) : 4-6格 (電機最高轉速/n=4-6，n為正整數)。 2. 座標軸選項 → 垂直(值)軸 →範圍 : a. 最小值 : 0 。 b. 最大值 : 最大值 > 過載特性曲線中的最大扭矩、最大功率。 c. 單位 (主要) : 4-6格 (最大值/n=4-6，n為正整數)。 3. 轉折點 : a. 請以虛線下拉至橫軸與最靠近橫軸的縱軸格線之間。（如下圖範例） b. 若不只一個轉折點請複製虛線、文字方塊"請填轉折點轉速"。 4. TNCurve、PNCurve : a. 請將 定扭力數值Nm、定功率數值kW 配置於定扭力區、定功率區(水平線)的上方。 b. 若版面空間不夠，則建議修改縱軸Scale的格數/配置於水平線的下方。 5. TNCurve、PNCurve: a. "S1-Cont."： 配置於工作區涵蓋範圍中。 若版面空間不夠，則使用箭頭指向工作區涵蓋範圍。 b. "工作制+單位&(0), (M), (S)"：(S2、S3/S6) 使用箭頭指向工作區涵蓋範圍。 c. "S2-Nmin"，其中N為正整數。 "S3/S6 N%"，其中N=60%、40%、25%、15%。 d. 驅動器選型-級數-工作制--對應關係（如下圖範例）。 S1-Cont. 大一級：S2-30min (0, M)→(大二級所需驅動器可應用在大一級的過載狀況) 大二級：S3/S6 15% (M) 6. 曲線請自行更改對應數列，使得轉折點不為平滑曲線。 7. 建議於解析度1920*1080之顯示器開啟檔案以防止圖面跑版。
C4: TN curve | K4: PN curve
C26: Ex. | K26: Ex.
C38: 此欄位自動計算請勿修改
C39: S1 100%負載連續使用測試 | D39: 電機轉速(RPM) (作圖) | F39: 量測轉矩(Nm) | H39: 設定轉矩(Nm) (作圖) | J39: 量測輸出功率(kW) | L39: 設定轉矩換算功率(kW)(作圖)
D40: 0 | F40: =電機廠報告與驗收規範!N3 -> 70 | H40: =電機廠報告與驗收規範!N3 -> 70 | J40: 0 | L40: 0
D41: =電機廠報告與驗收規範!$K33 -> 750 | F41: =電機廠報告與驗收規範!P33 -> 70.14 | H41: =電機廠報告與驗收規範!M33 -> 70 | J41: =電機廠報告與驗收規範!$X33 -> 5.5 | L41: =ROUND(2*PI()*D41*H41/60/1000,2) -> 5.5
D42: =電機廠報告與驗收規範!$K34 -> 1500 | F42: =電機廠報告與驗收規範!P34 -> 69.36 | H42: =電機廠報告與驗收規範!M34 -> 70 | J42: =電機廠報告與驗收規範!$X34 -> 10.91 | L42: =ROUND(2*PI()*D42*H42/60/1000,2) -> 11
D43: =IF(電機廠報告與驗收規範!$K35>電機廠報告與驗收規範!$H$5,電機廠報告與驗收規範!$H$5,電機廠報告與驗收規範!$K35) -> 2250 | F43: =IF(電機廠報告與驗收規範!$K35>電機廠報告與驗收規範!$H$5,電機廠報告與驗收規範!$P$41,電機廠報告與驗收規範!$P35) -> 0 | H43: =IF(電機廠報告與驗收規範!$K35>電機廠報告與驗收規範!$H$5,電機廠報告與驗收規範!$M$41,電機廠報告與驗收規範!$M35) -> 46.666667 | J43: =IF(電機廠報告與驗收規範!$K35>電機廠報告與驗收規範!$H$5,電機廠報告與驗收規範!$X$41,電機廠報告與驗收規範!$X35) -> 0 | L43: =ROUND(2*PI()*D43*H43/60/1000,2) -> 11
D44: =IF(電機廠報告與驗收規範!$K36>電機廠報告與驗收規範!$H$5,電機廠報告與驗收規範!$H$5,電機廠報告與驗收規範!$K36) -> 3000 | F44: =IF(電機廠報告與驗收規範!$K36>電機廠報告與驗收規範!$H$5,電機廠報告與驗收規範!$P$41,電機廠報告與驗收規範!$P36) -> 0 | H44: =IF(電機廠報告與驗收規範!$K36>電機廠報告與驗收規範!$H$5,電機廠報告與驗收規範!$M$41,電機廠報告與驗收規範!$M36) -> 35 | J44: =IF(電機廠報告與驗收規範!$K36>電機廠報告與驗收規範!$H$5,電機廠報告與驗收規範!$X$41,電機廠報告與驗收規範!$X36) -> 0 | L44: =ROUND(2*PI()*D44*H44/60/1000,2) -> 11
D45: =IF(電機廠報告與驗收規範!$K37>電機廠報告與驗收規範!$H$5,電機廠報告與驗收規範!$H$5,電機廠報告與驗收規範!$K37) -> 3750 | F45: =IF(電機廠報告與驗收規範!$K37>電機廠報告與驗收規範!$H$5,電機廠報告與驗收規範!$P$41,電機廠報告與驗收規範!$P37) -> 0 | H45: =IF(電機廠報告與驗收規範!$K37>電機廠報告與驗收規範!$H$5,電機廠報告與驗收規範!$M$41,電機廠報告與驗收規範!$M37) -> 28 | J45: =IF(電機廠報告與驗收規範!$K37>電機廠報告與驗收規範!$H$5,電機廠報告與驗收規範!$X$41,電機廠報告與驗收規範!$X37) -> 0 | L45: =ROUND(2*PI()*D45*H45/60/1000,2) -> 11
D46: =IF(電機廠報告與驗收規範!$K38>電機廠報告與驗收規範!$H$5,電機廠報告與驗收規範!$H$5,電機廠報告與驗收規範!$K38) -> 4500 | F46: =IF(電機廠報告與驗收規範!$K38>電機廠報告與驗收規範!$H$5,電機廠報告與驗收規範!$P$41,電機廠報告與驗收規範!$P38) -> 0 | H46: =IF(電機廠報告與驗收規範!$K38>電機廠報告與驗收規範!$H$5,電機廠報告與驗收規範!$M$41,電機廠報告與驗收規範!$M38) -> 23.333333 | J46: =IF(電機廠報告與驗收規範!$K38>電機廠報告與驗收規範!$H$5,電機廠報告與驗收規範!$X$41,電機廠報告與驗收規範!$X38) -> 0 | L46: =ROUND(2*PI()*D46*H46/60/1000,2) -> 11
D47: =IF(電機廠報告與驗收規範!$K39>電機廠報告與驗收規範!$H$5,電機廠報告與驗收規範!$H$5,電機廠報告與驗收規範!$K39) -> 5250 | F47: =IF(電機廠報告與驗收規範!$K39>電機廠報告與驗收規範!$H$5,電機廠報告與驗收規範!$P$41,電機廠報告與驗收規範!$P39) -> 0 | H47: =IF(電機廠報告與驗收規範!$K39>電機廠報告與驗收規範!$H$5,電機廠報告與驗收規範!$M$41,電機廠報告與驗收規範!$M39) -> 20 | J47: =IF(電機廠報告與驗收規範!$K39>電機廠報告與驗收規範!$H$5,電機廠報告與驗收規範!$X$41,電機廠報告與驗收規範!$X39) -> 0 | L47: =ROUND(2*PI()*D47*H47/60/1000,2) -> 11
D48: =IF(電機廠報告與驗收規範!$K40>電機廠報告與驗收規範!$H$5,電機廠報告與驗收規範!$H$5,電機廠報告與驗收規範!$K40) -> 6000 | F48: =IF(電機廠報告與驗收規範!$K40>電機廠報告與驗收規範!$H$5,電機廠報告與驗收規範!$P$41,電機廠報告與驗收規範!$P40) -> 0 | H48: =IF(電機廠報告與驗收規範!$K40>電機廠報告與驗收規範!$H$5,電機廠報告與驗收規範!$M$41,電機廠報告與驗收規範!$M40) -> 17.5 | J48: =IF(電機廠報告與驗收規範!$K40>電機廠報告與驗收規範!$H$5,電機廠報告與驗收規範!$X$41,電機廠報告與驗收規範!$X40) -> 0 | L48: =ROUND(2*PI()*D48*H48/60/1000,2) -> 11
D49: =IF(電機廠報告與驗收規範!$K41>電機廠報告與驗收規範!$H$5,電機廠報告與驗收規範!$H$5,電機廠報告與驗收規範!$K41) -> 8000 | F49: =IF(電機廠報告與驗收規範!$K41>電機廠報告與驗收規範!$H$5,電機廠報告與驗收規範!$P$41,電機廠報告與驗收規範!$P41) -> 0 | H49: =IF(電機廠報告與驗收規範!$K41>電機廠報告與驗收規範!$H$5,電機廠報告與驗收規範!$M$41,電機廠報告與驗收規範!$M41) -> 13.125 | J49: =IF(電機廠報告與驗收規範!$K41>電機廠報告與驗收規範!$H$5,電機廠報告與驗收規範!$X$41,電機廠報告與驗收規範!$X41) -> 0 | L49: =ROUND(2*PI()*D49*H49/60/1000,2) -> 11
C50: S2 短時間使用150%負載測試 [ S2 N min. ] | D50: 電機轉速(RPM) (作圖) | F50: 量測轉矩(Nm) | H50: 設定轉矩(Nm) (作圖) | J50: 量測輸出功率(kW) | L50: 設定轉矩換算功率(kW)(作圖)
D51: 0 | F51: =電機廠報告與驗收規範!N3*電機廠報告與驗收規範!L44 -> 105 | H51: =電機廠報告與驗收規範!N3*電機廠報告與驗收規範!L44 -> 105 | J51: 0 | L51: 0
D52: =電機廠報告與驗收規範!$K44 -> 750 | F52: =電機廠報告與驗收規範!P44 -> 105.3 | H52: =電機廠報告與驗收規範!M44 -> 105 | J52: =電機廠報告與驗收規範!$X44 -> 8.27 | L52: =ROUND(2*PI()*D52*H52/60/1000,2) -> 8.25
D53: =電機廠報告與驗收規範!$K45 -> 1500 | F53: =電機廠報告與驗收規範!P45 -> 105.9 | H53: =電機廠報告與驗收規範!M45 -> 105 | J53: =電機廠報告與驗收規範!$X45 -> 16.4 | L53: =ROUND(2*PI()*D53*H53/60/1000,2) -> 16.49
D54: =IF(電機廠報告與驗收規範!$K46>電機廠報告與驗收規範!$H$5,電機廠報告與驗收規範!$H$5,電機廠報告與驗收規範!$K46) -> 2250 | F54: =IF(電機廠報告與驗收規範!$K46>電機廠報告與驗收規範!$H$5,電機廠報告與驗收規範!$P$52,電機廠報告與驗收規範!$P46) -> 0 | H54: =IF(電機廠報告與驗收規範!$K46>電機廠報告與驗收規範!$H$5,電機廠報告與驗收規範!$M$52,電機廠報告與驗收規範!$M46) -> 70 | J54: =IF(電機廠報告與驗收規範!$K46>電機廠報告與驗收規範!$H$5,電機廠報告與驗收規範!$X$52,電機廠報告與驗收規範!$X46) -> 0 | L54: =ROUND(2*PI()*D54*H54/60/1000,2) -> 16.49
D55: =IF(電機廠報告與驗收規範!$K47>電機廠報告與驗收規範!$H$5,電機廠報告與驗收規範!$H$5,電機廠報告與驗收規範!$K47) -> 3000 | F55: =IF(電機廠報告與驗收規範!$K47>電機廠報告與驗收規範!$H$5,電機廠報告與驗收規範!$P$52,電機廠報告與驗收規範!$P47) -> 0 | H55: =IF(電機廠報告與驗收規範!$K47>電機廠報告與驗收規範!$H$5,電機廠報告與驗收規範!$M$52,電機廠報告與驗收規範!$M47) -> 52.5 | J55: =IF(電機廠報告與驗收規範!$K47>電機廠報告與驗收規範!$H$5,電機廠報告與驗收規範!$X$52,電機廠報告與驗收規範!$X47) -> 0 | L55: =ROUND(2*PI()*D55*H55/60/1000,2) -> 16.49
D56: =IF(電機廠報告與驗收規範!$K48>電機廠報告與驗收規範!$H$5,電機廠報告與驗收規範!$H$5,電機廠報告與驗收規範!$K48) -> 3750 | F56: =IF(電機廠報告與驗收規範!$K48>電機廠報告與驗收規範!$H$5,電機廠報告與驗收規範!$P$52,電機廠報告與驗收規範!$P48) -> 0 | H56: =IF(電機廠報告與驗收規範!$K48>電機廠報告與驗收規範!$H$5,電機廠報告與驗收規範!$M$52,電機廠報告與驗收規範!$M48) -> 42 | J56: =IF(電機廠報告與驗收規範!$K48>電機廠報告與驗收規範!$H$5,電機廠報告與驗收規範!$X$52,電機廠報告與驗收規範!$X48) -> 0 | L56: =ROUND(2*PI()*D56*H56/60/1000,2) -> 16.49
D57: =IF(電機廠報告與驗收規範!$K49>電機廠報告與驗收規範!$H$5,電機廠報告與驗收規範!$H$5,電機廠報告與驗收規範!$K49) -> 4500 | F57: =IF(電機廠報告與驗收規範!$K49>電機廠報告與驗收規範!$H$5,電機廠報告與驗收規範!$P$52,電機廠報告與驗收規範!$P49) -> 0 | H57: =IF(電機廠報告與驗收規範!$K49>電機廠報告與驗收規範!$H$5,電機廠報告與驗收規範!$M$52,電機廠報告與驗收規範!$M49) -> 35 | J57: =IF(電機廠報告與驗收規範!$K49>電機廠報告與驗收規範!$H$5,電機廠報告與驗收規範!$X$52,電機廠報告與驗收規範!$X49) -> 0 | L57: =ROUND(2*PI()*D57*H57/60/1000,2) -> 16.49
D58: =IF(電機廠報告與驗收規範!$K50>電機廠報告與驗收規範!$H$5,電機廠報告與驗收規範!$H$5,電機廠報告與驗收規範!$K50) -> 5250 | F58: =IF(電機廠報告與驗收規範!$K50>電機廠報告與驗收規範!$H$5,電機廠報告與驗收規範!$P$52,電機廠報告與驗收規範!$P50) -> 0 | H58: =IF(電機廠報告與驗收規範!$K50>電機廠報告與驗收規範!$H$5,電機廠報告與驗收規範!$M$52,電機廠報告與驗收規範!$M50) -> 30 | J58: =IF(電機廠報告與驗收規範!$K50>電機廠報告與驗收規範!$H$5,電機廠報告與驗收規範!$X$52,電機廠報告與驗收規範!$X50) -> 0 | L58: =ROUND(2*PI()*D58*H58/60/1000,2) -> 16.49
D59: =IF(電機廠報告與驗收規範!$K51>電機廠報告與驗收規範!$H$5,電機廠報告與驗收規範!$H$5,電機廠報告與驗收規範!$K51) -> 6000 | F59: =IF(電機廠報告與驗收規範!$K51>電機廠報告與驗收規範!$H$5,電機廠報告與驗收規範!$P$52,電機廠報告與驗收規範!$P51) -> 0 | H59: =IF(電機廠報告與驗收規範!$K51>電機廠報告與驗收規範!$H$5,電機廠報告與驗收規範!$M$52,電機廠報告與驗收規範!$M51) -> 26.25 | J59: =IF(電機廠報告與驗收規範!$K51>電機廠報告與驗收規範!$H$5,電機廠報告與驗收規範!$X$52,電機廠報告與驗收規範!$X51) -> 0 | L59: =ROUND(2*PI()*D59*H59/60/1000,2) -> 16.49
D60: =IF(電機廠報告與驗收規範!$K52>電機廠報告與驗收規範!$H$5,電機廠報告與驗收規範!$H$5,電機廠報告與驗收規範!$K52) -> 8000 | F60: =IF(電機廠報告與驗收規範!$K52>電機廠報告與驗收規範!$H$5,電機廠報告與驗收規範!$P$52,電機廠報告與驗收規範!$P52) -> 0 | H60: =IF(電機廠報告與驗收規範!$K52>電機廠報告與驗收規範!$H$5,電機廠報告與驗收規範!$M$52,電機廠報告與驗收規範!$M52) -> 19.6875 | J60: =IF(電機廠報告與驗收規範!$K52>電機廠報告與驗收規範!$H$5,電機廠報告與驗收規範!$X$52,電機廠報告與驗收規範!$X52) -> 0 | L60: =ROUND(2*PI()*D60*H60/60/1000,2) -> 16.49
C61: S3 / S6 反覆使用測試 [ S3 / S6 10% 10min. ] | D61: 電機轉速(RPM) (作圖) | F61: 量測轉矩(Nm) | H61: 設定轉矩(Nm) (作圖) | J61: 量測輸出功率(kW) | L61: 設定轉矩換算功率(kW)(作圖)
D62: 0 | F62: =MAX(電機廠報告與驗收規範!N56,電機廠報告與驗收規範!N57,電機廠報告與驗收規範!N58) -> 140 | H62: =MAX(電機廠報告與驗收規範!N56,電機廠報告與驗收規範!N57,電機廠報告與驗收規範!N58) -> 140 | J62: 0 | L62: 0
D63: =IF(電機廠報告與驗收規範!$N58=電機廠報告與驗收規範!$J$5,電機廠報告與驗收規範!$L58,IF(AND(電機廠報告與驗收規範!$N57>電機廠報告與驗收規範!$N58,電機廠報告與驗收規範!$N57=電機廠報告與驗收規範!$J$5),電機廠報告與驗收規範!$L57,電機廠報告與驗收規範!$L56)) -> 1500 | F63: =IF(電機廠報告與驗收規範!$N58=電機廠報告與驗收規範!$J$5,電機廠報告與驗收規範!$Q58,IF(AND(電機廠報告與驗收規範!$N57>電機廠報告與驗收規範!$N58,電機廠報告與驗收規範!$N57=電機廠報告與驗收規範!$J$5),電機廠報告與驗收規範!$Q57,電機廠報告與驗收規範!$Q56)) -> 140.65 | H63: =IF(電機廠報告與驗收規範!$N58=電機廠報告與驗收規範!$J$5,電機廠報告與驗收規範!$N58,IF(AND(電機廠報告與驗收規範!$N57>電機廠報告與驗收規範!$N58,電機廠報告與驗收規範!$N57=電機廠報告與驗收規範!$J$5),電機廠報告與驗收規範!$N57,電機廠報告與驗收規範!$N56)) -> 140 | J63: =IF(電機廠報告與驗收規範!$N58=電機廠報告與驗收規範!$J$5,電機廠報告與驗收規範!$U58,IF(AND(電機廠報告與驗收規範!$N57>電機廠報告與驗收規範!$N58,電機廠報告與驗收規範!$N57=電機廠報告與驗收規範!$J$5),電機廠報告與驗收規範!$U57,電機廠報告與驗收規範!$U56)) -> 21.9 | L63: =ROUND(2*PI()*D63*H63/60/1000,2) -> 21.99
D64: =IF(電機廠報告與驗收規範!$N59=電機廠報告與驗收規範!$J$5,電機廠報告與驗收規範!$L59,IF(AND(電機廠報告與驗收規範!$N58>電機廠報告與驗收規範!$N59,電機廠報告與驗收規範!$N58=電機廠報告與驗收規範!$J$5),電機廠報告與驗收規範!$L58,電機廠報告與驗收規範!$L57)) -> 1500 | F64: =IF(電機廠報告與驗收規範!$N59=電機廠報告與驗收規範!$J$5,電機廠報告與驗收規範!$Q59,IF(AND(電機廠報告與驗收規範!$N58>電機廠報告與驗收規範!$N59,電機廠報告與驗收規範!$N58=電機廠報告與驗收規範!$J$5),電機廠報告與驗收規範!$Q58,電機廠報告與驗收規範!$Q57)) -> 140.65 | H64: =IF(電機廠報告與驗收規範!$N59=電機廠報告與驗收規範!$J$5,電機廠報告與驗收規範!$N59,IF(AND(電機廠報告與驗收規範!$N58>電機廠報告與驗收規範!$N59,電機廠報告與驗收規範!$N58=電機廠報告與驗收規範!$J$5),電機廠報告與驗收規範!$N58,電機廠報告與驗收規範!$N57)) -> 140 | J64: =IF(電機廠報告與驗收規範!$N59=電機廠報告與驗收規範!$J$5,電機廠報告與驗收規範!$U59,IF(AND(電機廠報告與驗收規範!$N58>電機廠報告與驗收規範!$N59,電機廠報告與驗收規範!$N58=電機廠報告與驗收規範!$J$5),電機廠報告與驗收規範!$U58,電機廠報告與驗收規範!$U57)) -> 21.9 | L64: =ROUND(2*PI()*D64*H64/60/1000,2) -> 21.99
D65: =IF(電機廠報告與驗收規範!$N60=電機廠報告與驗收規範!$J$5,電機廠報告與驗收規範!$L60,IF(AND(電機廠報告與驗收規範!$N59>電機廠報告與驗收規範!$N60,電機廠報告與驗收規範!$N59=電機廠報告與驗收規範!$J$5),電機廠報告與驗收規範!$L59,電機廠報告與驗收規範!$L58)) -> 1500 | F65: =IF(電機廠報告與驗收規範!$N60=電機廠報告與驗收規範!$J$5,電機廠報告與驗收規範!$Q60,IF(AND(電機廠報告與驗收規範!$N59>電機廠報告與驗收規範!$N60,電機廠報告與驗收規範!$N59=電機廠報告與驗收規範!$J$5),電機廠報告與驗收規範!$Q59,電機廠報告與驗收規範!$Q58)) -> 140.65 | H65: =IF(電機廠報告與驗收規範!$N60=電機廠報告與驗收規範!$J$5,電機廠報告與驗收規範!$N60,IF(AND(電機廠報告與驗收規範!$N59>電機廠報告與驗收規範!$N60,電機廠報告與驗收規範!$N59=電機廠報告與驗收規範!$J$5),電機廠報告與驗收規範!$N59,電機廠報告與驗收規範!$N58)) -> 140 | J65: =IF(電機廠報告與驗收規範!$N60=電機廠報告與驗收規範!$J$5,電機廠報告與驗收規範!$U60,IF(AND(電機廠報告與驗收規範!$N59>電機廠報告與驗收規範!$N60,電機廠報告與驗收規範!$N59=電機廠報告與驗收規範!$J$5),電機廠報告與驗收規範!$U59,電機廠報告與驗收規範!$U58)) -> 21.9 | L65: =ROUND(2*PI()*D65*H65/60/1000,2) -> 21.99
D66: =IF(IF(電機廠報告與驗收規範!$N61=電機廠報告與驗收規範!$J$5,電機廠報告與驗收規範!$L61,IF(AND(電機廠報告與驗收規範!$N60>電機廠報告與驗收規範!$N61,電機廠報告與驗收規範!$N60=電機廠報告與驗收規範!$J$5),電機廠報告與驗收規範!$L60,電機廠報告與驗收規範!$L59))>電機廠報告與驗收規範!$H$5,電機廠報告與驗收規範!$H$5,IF(電機廠報告與驗收規範!$N61=電機廠報告與驗收規範!$J$5,電機廠報告與驗收規範!$L61,IF(AND(電機廠報告與驗收規範!$N60>電機廠報告與驗收規範!$N61,電機廠報告與驗收規範!$N60=電機廠報告與驗收規範!$J$5),電機廠報告與驗收規範!$L60,電機廠報告與驗收規範!$L59))) -> 2250 | F66: =IF(IF(電機廠報告與驗收規範!$N61=電機廠報告與驗收規範!$J$5,電機廠報告與驗收規範!$L61,IF(AND(電機廠報告與驗收規範!$N60>電機廠報告與驗收規範!$N61,電機廠報告與驗收規範!$N60=電機廠報告與驗收規範!$J$5),電機廠報告與驗收規範!$L60,電機廠報告與驗收規範!$L59))>電機廠報告與驗收規範!$H$5,電機廠報告與驗收規範!$Q$65,IF(IF(電機廠報告與驗收規範!$N60=電機廠報告與驗收規範!$J$5,電機廠報告與驗收規範!$L60,IF(AND(電機廠報告與驗收規範!$N59>電機廠報告與驗收規範!$N60,電機廠報告與驗收規範!$N59=電機廠報告與驗收規範!$J$5),電機廠報告與驗收規範!$L59,電機廠報告與驗收規範!$L58))=電機廠報告與驗收規範!$L58,電機廠報告與驗收規範!$Q59,IF(IF(電機廠報告與驗收規範!$N60=電機廠報告與驗收規範!$J$5,電機廠報告與驗收規範!$L60,IF(AND(電機廠報告與驗收規範!$N59>電機廠報告與驗收規範!$N60,電機廠報告與驗收規範!$N59=電機廠報告與驗收規範!$J$5),電機廠報告與驗收規範!$L59,電機廠報告與驗收規範!$L58))=電機廠報告與驗收規範!$L57,電機廠報告與驗收規範!$Q58,電機廠報告與驗收規範!$Q57))) -> 0 | H66: =IF(IF(電機廠報告與驗收規範!$N61=電機廠報告與驗收規範!$J$5,電機廠報告與驗收規範!$L61,IF(AND(電機廠報告與驗收規範!$N60>電機廠報告與驗收規範!$N61,電機廠報告與驗收規範!$N60=電機廠報告與驗收規範!$J$5),電機廠報告與驗收規範!$L60,電機廠報告與驗收規範!$L59))>電機廠報告與驗收規範!$H$5,電機廠報告與驗收規範!$N$65,IF(IF(電機廠報告與驗收規範!$N60=電機廠報告與驗收規範!$J$5,電機廠報告與驗收規範!$L60,IF(AND(電機廠報告與驗收規範!$N59>電機廠報告與驗收規範!$N60,電機廠報告與驗收規範!$N59=電機廠報告與驗收規範!$J$5),電機廠報告與驗收規範!$L59,電機廠報告與驗收規範!$L58))=電機廠報告與驗收規範!$L58,電機廠報告與驗收規範!$N59,IF(IF(電機廠報告與驗收規範!$N60=電機廠報告與驗收規範!$J$5,電機廠報告與驗收規範!$L60,IF(AND(電機廠報告與驗收規範!$N59>電機廠報告與驗收規範!$N60,電機廠報告與驗收規範!$N59=電機廠報告與驗收規範!$J$5),電機廠報告與驗收規範!$L59,電機廠報告與驗收規範!$L58))=電機廠報告與驗收規範!$L57,電機廠報告與驗收規範!$N58,電機廠報告與驗收規範!$N57))) -> 93.333333 | J66: =IF(IF(電機廠報告與驗收規範!$N61=電機廠報告與驗收規範!$J$5,電機廠報告與驗收規範!$L61,IF(AND(電機廠報告與驗收規範!$N60>電機廠報告與驗收規範!$N61,電機廠報告與驗收規範!$N60=電機廠報告與驗收規範!$J$5),電機廠報告與驗收規範!$L60,電機廠報告與驗收規範!$L59))>電機廠報告與驗收規範!$H$5,電機廠報告與驗收規範!$U$65,IF(IF(電機廠報告與驗收規範!$N60=電機廠報告與驗收規範!$J$5,電機廠報告與驗收規範!$L60,IF(AND(電機廠報告與驗收規範!$N59>電機廠報告與驗收規範!$N60,電機廠報告與驗收規範!$N59=電機廠報告與驗收規範!$J$5),電機廠報告與驗收規範!$L59,電機廠報告與驗收規範!$L58))=電機廠報告與驗收規範!$L58,電機廠報告與驗收規範!$U59,IF(IF(電機廠報告與驗收規範!$N60=電機廠報告與驗收規範!$J$5,電機廠報告與驗收規範!$L60,IF(AND(電機廠報告與驗收規範!$N59>電機廠報告與驗收規範!$N60,電機廠報告與驗收規範!$N59=電機廠報告與驗收規範!$J$5),電機廠報告與驗收規範!$L59,電機廠報告與驗收規範!$L58))=電機廠報告與驗收規範!$L57,電機廠報告與驗收規範!$U58,電機廠報告與驗收規範!$U57))) -> 0 | L66: =ROUND(2*PI()*D66*H66/60/1000,2) -> 21.99
D67: =IF(IF(電機廠報告與驗收規範!$N62=電機廠報告與驗收規範!$J$5,電機廠報告與驗收規範!$L62,IF(AND(電機廠報告與驗收規範!$N61>電機廠報告與驗收規範!$N62,電機廠報告與驗收規範!$N61=電機廠報告與驗收規範!$J$5),電機廠報告與驗收規範!$L61,電機廠報告與驗收規範!$L60))>電機廠報告與驗收規範!$H$5,電機廠報告與驗收規範!$H$5,IF(電機廠報告與驗收規範!$N62=電機廠報告與驗收規範!$J$5,電機廠報告與驗收規範!$L62,IF(AND(電機廠報告與驗收規範!$N61>電機廠報告與驗收規範!$N62,電機廠報告與驗收規範!$N61=電機廠報告與驗收規範!$J$5),電機廠報告與驗收規範!$L61,電機廠報告與驗收規範!$L60))) -> 3000 | F67: =IF(IF(電機廠報告與驗收規範!$N62=電機廠報告與驗收規範!$J$5,電機廠報告與驗收規範!$L62,IF(AND(電機廠報告與驗收規範!$N61>電機廠報告與驗收規範!$N62,電機廠報告與驗收規範!$N61=電機廠報告與驗收規範!$J$5),電機廠報告與驗收規範!$L61,電機廠報告與驗收規範!$L60))>電機廠報告與驗收規範!$H$5,電機廠報告與驗收規範!$Q$65,IF(IF(電機廠報告與驗收規範!$N61=電機廠報告與驗收規範!$J$5,電機廠報告與驗收規範!$L61,IF(AND(電機廠報告與驗收規範!$N60>電機廠報告與驗收規範!$N61,電機廠報告與驗收規範!$N60=電機廠報告與驗收規範!$J$5),電機廠報告與驗收規範!$L60,電機廠報告與驗收規範!$L59))=電機廠報告與驗收規範!$L59,電機廠報告與驗收規範!$Q60,IF(IF(電機廠報告與驗收規範!$N61=電機廠報告與驗收規範!$J$5,電機廠報告與驗收規範!$L61,IF(AND(電機廠報告與驗收規範!$N60>電機廠報告與驗收規範!$N61,電機廠報告與驗收規範!$N60=電機廠報告與驗收規範!$J$5),電機廠報告與驗收規範!$L60,電機廠報告與驗收規範!$L59))=電機廠報告與驗收規範!$L58,電機廠報告與驗收規範!$Q59,電機廠報告與驗收規範!$Q58))) -> 0 | H67: =IF(IF(電機廠報告與驗收規範!$N62=電機廠報告與驗收規範!$J$5,電機廠報告與驗收規範!$L62,IF(AND(電機廠報告與驗收規範!$N61>電機廠報告與驗收規範!$N62,電機廠報告與驗收規範!$N61=電機廠報告與驗收規範!$J$5),電機廠報告與驗收規範!$L61,電機廠報告與驗收規範!$L60))>電機廠報告與驗收規範!$H$5,電機廠報告與驗收規範!$N$65,IF(IF(電機廠報告與驗收規範!$N61=電機廠報告與驗收規範!$J$5,電機廠報告與驗收規範!$L61,IF(AND(電機廠報告與驗收規範!$N60>電機廠報告與驗收規範!$N61,電機廠報告與驗收規範!$N60=電機廠報告與驗收規範!$J$5),電機廠報告與驗收規範!$L60,電機廠報告與驗收規範!$L59))=電機廠報告與驗收規範!$L59,電機廠報告與驗收規範!$N60,IF(IF(電機廠報告與驗收規範!$N61=電機廠報告與驗收規範!$J$5,電機廠報告與驗收規範!$L61,IF(AND(電機廠報告與驗收規範!$N60>電機廠報告與驗收規範!$N61,電機廠報告與驗收規範!$N60=電機廠報告與驗收規範!$J$5),電機廠報告與驗收規範!$L60,電機廠報告與驗收規範!$L59))=電機廠報告與驗收規範!$L58,電機廠報告與驗收規範!$N59,電機廠報告與驗收規範!$N58))) -> 70 | J67: =IF(IF(電機廠報告與驗收規範!$N62=電機廠報告與驗收規範!$J$5,電機廠報告與驗收規範!$L62,IF(AND(電機廠報告與驗收規範!$N61>電機廠報告與驗收規範!$N62,電機廠報告與驗收規範!$N61=電機廠報告與驗收規範!$J$5),電機廠報告與驗收規範!$L61,電機廠報告與驗收規範!$L60))>電機廠報告與驗收規範!$H$5,電機廠報告與驗收規範!$U$65,IF(IF(電機廠報告與驗收規範!$N61=電機廠報告與驗收規範!$J$5,電機廠報告與驗收規範!$L61,IF(AND(電機廠報告與驗收規範!$N60>電機廠報告與驗收規範!$N61,電機廠報告與驗收規範!$N60=電機廠報告與驗收規範!$J$5),電機廠報告與驗收規範!$L60,電機廠報告與驗收規範!$L59))=電機廠報告與驗收規範!$L59,電機廠報告與驗收規範!$U60,IF(IF(電機廠報告與驗收規範!$N61=電機廠報告與驗收規範!$J$5,電機廠報告與驗收規範!$L61,IF(AND(電機廠報告與驗收規範!$N60>電機廠報告與驗收規範!$N61,電機廠報告與驗收規範!$N60=電機廠報告與驗收規範!$J$5),電機廠報告與驗收規範!$L60,電機廠報告與驗收規範!$L59))=電機廠報告與驗收規範!$L58,電機廠報告與驗收規範!$U59,電機廠報告與驗收規範!$U58))) -> 0 | L67: =ROUND(2*PI()*D67*H67/60/1000,2) -> 21.99
D68: =IF(IF(電機廠報告與驗收規範!$N63=電機廠報告與驗收規範!$J$5,電機廠報告與驗收規範!$L63,IF(AND(電機廠報告與驗收規範!$N62>電機廠報告與驗收規範!$N63,電機廠報告與驗收規範!$N62=電機廠報告與驗收規範!$J$5),電機廠報告與驗收規範!$L62,電機廠報告與驗收規範!$L61))>電機廠報告與驗收規範!$H$5,電機廠報告與驗收規範!$H$5,IF(電機廠報告與驗收規範!$N63=電機廠報告與驗收規範!$J$5,電機廠報告與驗收規範!$L63,IF(AND(電機廠報告與驗收規範!$N62>電機廠報告與驗收規範!$N63,電機廠報告與驗收規範!$N62=電機廠報告與驗收規範!$J$5),電機廠報告與驗收規範!$L62,電機廠報告與驗收規範!$L61))) -> 3750 | F68: =IF(IF(電機廠報告與驗收規範!$N63=電機廠報告與驗收規範!$J$5,電機廠報告與驗收規範!$L63,IF(AND(電機廠報告與驗收規範!$N62>電機廠報告與驗收規範!$N63,電機廠報告與驗收規範!$N62=電機廠報告與驗收規範!$J$5),電機廠報告與驗收規範!$L62,電機廠報告與驗收規範!$L61))>電機廠報告與驗收規範!$H$5,電機廠報告與驗收規範!$Q$65,IF(IF(電機廠報告與驗收規範!$N62=電機廠報告與驗收規範!$J$5,電機廠報告與驗收規範!$L62,IF(AND(電機廠報告與驗收規範!$N61>電機廠報告與驗收規範!$N62,電機廠報告與驗收規範!$N61=電機廠報告與驗收規範!$J$5),電機廠報告與驗收規範!$L61,電機廠報告與驗收規範!$L60))=電機廠報告與驗收規範!$L60,電機廠報告與驗收規範!$Q61,IF(IF(電機廠報告與驗收規範!$N62=電機廠報告與驗收規範!$J$5,電機廠報告與驗收規範!$L62,IF(AND(電機廠報告與驗收規範!$N61>電機廠報告與驗收規範!$N62,電機廠報告與驗收規範!$N61=電機廠報告與驗收規範!$J$5),電機廠報告與驗收規範!$L61,電機廠報告與驗收規範!$L60))=電機廠報告與驗收規範!$L59,電機廠報告與驗收規範!$Q60,電機廠報告與驗收規範!$Q59))) -> 0 | H68: =IF(IF(電機廠報告與驗收規範!$N63=電機廠報告與驗收規範!$J$5,電機廠報告與驗收規範!$L63,IF(AND(電機廠報告與驗收規範!$N62>電機廠報告與驗收規範!$N63,電機廠報告與驗收規範!$N62=電機廠報告與驗收規範!$J$5),電機廠報告與驗收規範!$L62,電機廠報告與驗收規範!$L61))>電機廠報告與驗收規範!$H$5,電機廠報告與驗收規範!$N$65,IF(IF(電機廠報告與驗收規範!$N62=電機廠報告與驗收規範!$J$5,電機廠報告與驗收規範!$L62,IF(AND(電機廠報告與驗收規範!$N61>電機廠報告與驗收規範!$N62,電機廠報告與驗收規範!$N61=電機廠報告與驗收規範!$J$5),電機廠報告與驗收規範!$L61,電機廠報告與驗收規範!$L60))=電機廠報告與驗收規範!$L60,電機廠報告與驗收規範!$N61,IF(IF(電機廠報告與驗收規範!$N62=電機廠報告與驗收規範!$J$5,電機廠報告與驗收規範!$L62,IF(AND(電機廠報告與驗收規範!$N61>電機廠報告與驗收規範!$N62,電機廠報告與驗收規範!$N61=電機廠報告與驗收規範!$J$5),電機廠報告與驗收規範!$L61,電機廠報告與驗收規範!$L60))=電機廠報告與驗收規範!$L59,電機廠報告與驗收規範!$N60,電機廠報告與驗收規範!$N59))) -> 56 | J68: =IF(IF(電機廠報告與驗收規範!$N63=電機廠報告與驗收規範!$J$5,電機廠報告與驗收規範!$L63,IF(AND(電機廠報告與驗收規範!$N62>電機廠報告與驗收規範!$N63,電機廠報告與驗收規範!$N62=電機廠報告與驗收規範!$J$5),電機廠報告與驗收規範!$L62,電機廠報告與驗收規範!$L61))>電機廠報告與驗收規範!$H$5,電機廠報告與驗收規範!$U$65,IF(IF(電機廠報告與驗收規範!$N62=電機廠報告與驗收規範!$J$5,電機廠報告與驗收規範!$L62,IF(AND(電機廠報告與驗收規範!$N61>電機廠報告與驗收規範!$N62,電機廠報告與驗收規範!$N61=電機廠報告與驗收規範!$J$5),電機廠報告與驗收規範!$L61,電機廠報告與驗收規範!$L60))=電機廠報告與驗收規範!$L60,電機廠報告與驗收規範!$U61,IF(IF(電機廠報告與驗收規範!$N62=電機廠報告與驗收規範!$J$5,電機廠報告與驗收規範!$L62,IF(AND(電機廠報告與驗收規範!$N61>電機廠報告與驗收規範!$N62,電機廠報告與驗收規範!$N61=電機廠報告與驗收規範!$J$5),電機廠報告與驗收規範!$L61,電機廠報告與驗收規範!$L60))=電機廠報告與驗收規範!$L59,電機廠報告與驗收規範!$U60,電機廠報告與驗收規範!$U59))) -> 0 | L68: =ROUND(2*PI()*D68*H68/60/1000,2) -> 21.99
D69: =IF(IF(電機廠報告與驗收規範!$N64=電機廠報告與驗收規範!$J$5,電機廠報告與驗收規範!$L64,IF(AND(電機廠報告與驗收規範!$N63>電機廠報告與驗收規範!$N64,電機廠報告與驗收規範!$N63=電機廠報告與驗收規範!$J$5),電機廠報告與驗收規範!$L63,電機廠報告與驗收規範!$L62))>電機廠報告與驗收規範!$H$5,電機廠報告與驗收規範!$H$5,IF(電機廠報告與驗收規範!$N64=電機廠報告與驗收規範!$J$5,電機廠報告與驗收規範!$L64,IF(AND(電機廠報告與驗收規範!$N63>電機廠報告與驗收規範!$N64,電機廠報告與驗收規範!$N63=電機廠報告與驗收規範!$J$5),電機廠報告與驗收規範!$L63,電機廠報告與驗收規範!$L62))) -> 4500 | F69: =IF(IF(電機廠報告與驗收規範!$N64=電機廠報告與驗收規範!$J$5,電機廠報告與驗收規範!$L64,IF(AND(電機廠報告與驗收規範!$N63>電機廠報告與驗收規範!$N64,電機廠報告與驗收規範!$N63=電機廠報告與驗收規範!$J$5),電機廠報告與驗收規範!$L63,電機廠報告與驗收規範!$L62))>電機廠報告與驗收規範!$H$5,電機廠報告與驗收規範!$Q$65,IF(IF(電機廠報告與驗收規範!$N63=電機廠報告與驗收規範!$J$5,電機廠報告與驗收規範!$L63,IF(AND(電機廠報告與驗收規範!$N62>電機廠報告與驗收規範!$N63,電機廠報告與驗收規範!$N62=電機廠報告與驗收規範!$J$5),電機廠報告與驗收規範!$L62,電機廠報告與驗收規範!$L61))=電機廠報告與驗收規範!$L61,電機廠報告與驗收規範!$Q62,IF(IF(電機廠報告與驗收規範!$N63=電機廠報告與驗收規範!$J$5,電機廠報告與驗收規範!$L63,IF(AND(電機廠報告與驗收規範!$N62>電機廠報告與驗收規範!$N63,電機廠報告與驗收規範!$N62=電機廠報告與驗收規範!$J$5),電機廠報告與驗收規範!$L62,電機廠報告與驗收規範!$L61))=電機廠報告與驗收規範!$L60,電機廠報告與驗收規範!$Q61,電機廠報告與驗收規範!$Q60))) -> 0 | H69: =IF(IF(電機廠報告與驗收規範!$N64=電機廠報告與驗收規範!$J$5,電機廠報告與驗收規範!$L64,IF(AND(電機廠報告與驗收規範!$N63>電機廠報告與驗收規範!$N64,電機廠報告與驗收規範!$N63=電機廠報告與驗收規範!$J$5),電機廠報告與驗收規範!$L63,電機廠報告與驗收規範!$L62))>電機廠報告與驗收規範!$H$5,電機廠報告與驗收規範!$N$65,IF(IF(電機廠報告與驗收規範!$N63=電機廠報告與驗收規範!$J$5,電機廠報告與驗收規範!$L63,IF(AND(電機廠報告與驗收規範!$N62>電機廠報告與驗收規範!$N63,電機廠報告與驗收規範!$N62=電機廠報告與驗收規範!$J$5),電機廠報告與驗收規範!$L62,電機廠報告與驗收規範!$L61))=電機廠報告與驗收規範!$L61,電機廠報告與驗收規範!$N62,IF(IF(電機廠報告與驗收規範!$N63=電機廠報告與驗收規範!$J$5,電機廠報告與驗收規範!$L63,IF(AND(電機廠報告與驗收規範!$N62>電機廠報告與驗收規範!$N63,電機廠報告與驗收規範!$N62=電機廠報告與驗收規範!$J$5),電機廠報告與驗收規範!$L62,電機廠報告與驗收規範!$L61))=電機廠報告與驗收規範!$L60,電機廠報告與驗收規範!$N61,電機廠報告與驗收規範!$N60))) -> 46.666667 | J69: =IF(IF(電機廠報告與驗收規範!$N64=電機廠報告與驗收規範!$J$5,電機廠報告與驗收規範!$L64,IF(AND(電機廠報告與驗收規範!$N63>電機廠報告與驗收規範!$N64,電機廠報告與驗收規範!$N63=電機廠報告與驗收規範!$J$5),電機廠報告與驗收規範!$L63,電機廠報告與驗收規範!$L62))>電機廠報告與驗收規範!$H$5,電機廠報告與驗收規範!$U$65,IF(IF(電機廠報告與驗收規範!$N63=電機廠報告與驗收規範!$J$5,電機廠報告與驗收規範!$L63,IF(AND(電機廠報告與驗收規範!$N62>電機廠報告與驗收規範!$N63,電機廠報告與驗收規範!$N62=電機廠報告與驗收規範!$J$5),電機廠報告與驗收規範!$L62,電機廠報告與驗收規範!$L61))=電機廠報告與驗收規範!$L61,電機廠報告與驗收規範!$U62,IF(IF(電機廠報告與驗收規範!$N63=電機廠報告與驗收規範!$J$5,電機廠報告與驗收規範!$L63,IF(AND(電機廠報告與驗收規範!$N62>電機廠報告與驗收規範!$N63,電機廠報告與驗收規範!$N62=電機廠報告與驗收規範!$J$5),電機廠報告與驗收規範!$L62,電機廠報告與驗收規範!$L61))=電機廠報告與驗收規範!$L60,電機廠報告與驗收規範!$U61,電機廠報告與驗收規範!$U60))) -> 0 | L69: =ROUND(2*PI()*D69*H69/60/1000,2) -> 21.99
D70: =IF(IF(電機廠報告與驗收規範!$N65=電機廠報告與驗收規範!$J$5,電機廠報告與驗收規範!$L65,IF(AND(電機廠報告與驗收規範!$N64>電機廠報告與驗收規範!$N65,電機廠報告與驗收規範!$N64=電機廠報告與驗收規範!$J$5),電機廠報告與驗收規範!$L64,電機廠報告與驗收規範!$L63))>電機廠報告與驗收規範!$H$5,電機廠報告與驗收規範!$H$5,IF(電機廠報告與驗收規範!$N65=電機廠報告與驗收規範!$J$5,電機廠報告與驗收規範!$L65,IF(AND(電機廠報告與驗收規範!$N64>電機廠報告與驗收規範!$N65,電機廠報告與驗收規範!$N64=電機廠報告與驗收規範!$J$5),電機廠報告與驗收規範!$L64,電機廠報告與驗收規範!$L63))) -> 5250 | F70: =IF(IF(電機廠報告與驗收規範!$N65=電機廠報告與驗收規範!$J$5,電機廠報告與驗收規範!$L65,IF(AND(電機廠報告與驗收規範!$N64>電機廠報告與驗收規範!$N65,電機廠報告與驗收規範!$N64=電機廠報告與驗收規範!$J$5),電機廠報告與驗收規範!$L64,電機廠報告與驗收規範!$L63))>電機廠報告與驗收規範!$H$5,電機廠報告與驗收規範!$Q$65,IF(IF(電機廠報告與驗收規範!$N64=電機廠報告與驗收規範!$J$5,電機廠報告與驗收規範!$L64,IF(AND(電機廠報告與驗收規範!$N63>電機廠報告與驗收規範!$N64,電機廠報告與驗收規範!$N63=電機廠報告與驗收規範!$J$5),電機廠報告與驗收規範!$L63,電機廠報告與驗收規範!$L62))=電機廠報告與驗收規範!$L62,電機廠報告與驗收規範!$Q63,IF(IF(電機廠報告與驗收規範!$N64=電機廠報告與驗收規範!$J$5,電機廠報告與驗收規範!$L64,IF(AND(電機廠報告與驗收規範!$N63>電機廠報告與驗收規範!$N64,電機廠報告與驗收規範!$N63=電機廠報告與驗收規範!$J$5),電機廠報告與驗收規範!$L63,電機廠報告與驗收規範!$L62))=電機廠報告與驗收規範!$L61,電機廠報告與驗收規範!$Q62,電機廠報告與驗收規範!$Q61))) -> 0 | H70: =IF(IF(電機廠報告與驗收規範!$N65=電機廠報告與驗收規範!$J$5,電機廠報告與驗收規範!$L65,IF(AND(電機廠報告與驗收規範!$N64>電機廠報告與驗收規範!$N65,電機廠報告與驗收規範!$N64=電機廠報告與驗收規範!$J$5),電機廠報告與驗收規範!$L64,電機廠報告與驗收規範!$L63))>電機廠報告與驗收規範!$H$5,電機廠報告與驗收規範!$N$65,IF(IF(電機廠報告與驗收規範!$N64=電機廠報告與驗收規範!$J$5,電機廠報告與驗收規範!$L64,IF(AND(電機廠報告與驗收規範!$N63>電機廠報告與驗收規範!$N64,電機廠報告與驗收規範!$N63=電機廠報告與驗收規範!$J$5),電機廠報告與驗收規範!$L63,電機廠報告與驗收規範!$L62))=電機廠報告與驗收規範!$L62,電機廠報告與驗收規範!$N63,IF(IF(電機廠報告與驗收規範!$N64=電機廠報告與驗收規範!$J$5,電機廠報告與驗收規範!$L64,IF(AND(電機廠報告與驗收規範!$N63>電機廠報告與驗收規範!$N64,電機廠報告與驗收規範!$N63=電機廠報告與驗收規範!$J$5),電機廠報告與驗收規範!$L63,電機廠報告與驗收規範!$L62))=電機廠報告與驗收規範!$L61,電機廠報告與驗收規範!$N62,電機廠報告與驗收規範!$N61))) -> 40 | J70: =IF(IF(電機廠報告與驗收規範!$N65=電機廠報告與驗收規範!$J$5,電機廠報告與驗收規範!$L65,IF(AND(電機廠報告與驗收規範!$N64>電機廠報告與驗收規範!$N65,電機廠報告與驗收規範!$N64=電機廠報告與驗收規範!$J$5),電機廠報告與驗收規範!$L64,電機廠報告與驗收規範!$L63))>電機廠報告與驗收規範!$H$5,電機廠報告與驗收規範!$U$65,IF(IF(電機廠報告與驗收規範!$N64=電機廠報告與驗收規範!$J$5,電機廠報告與驗收規範!$L64,IF(AND(電機廠報告與驗收規範!$N63>電機廠報告與驗收規範!$N64,電機廠報告與驗收規範!$N63=電機廠報告與驗收規範!$J$5),電機廠報告與驗收規範!$L63,電機廠報告與驗收規範!$L62))=電機廠報告與驗收規範!$L62,電機廠報告與驗收規範!$U63,IF(IF(電機廠報告與驗收規範!$N64=電機廠報告與驗收規範!$J$5,電機廠報告與驗收規範!$L64,IF(AND(電機廠報告與驗收規範!$N63>電機廠報告與驗收規範!$N64,電機廠報告與驗收規範!$N63=電機廠報告與驗收規範!$J$5),電機廠報告與驗收規範!$L63,電機廠報告與驗收規範!$L62))=電機廠報告與驗收規範!$L61,電機廠報告與驗收規範!$U62,電機廠報告與驗收規範!$U61))) -> 0 | L70: =ROUND(2*PI()*D70*H70/60/1000,2) -> 21.99
D71: =IF(IF(電機廠報告與驗收規範!$N66=電機廠報告與驗收規範!$J$5,電機廠報告與驗收規範!$L66,IF(AND(電機廠報告與驗收規範!$N65>電機廠報告與驗收規範!$N66,電機廠報告與驗收規範!$N65=電機廠報告與驗收規範!$J$5),電機廠報告與驗收規範!$L65,電機廠報告與驗收規範!$L64))>電機廠報告與驗收規範!$H$5,電機廠報告與驗收規範!$H$5,IF(電機廠報告與驗收規範!$N66=電機廠報告與驗收規範!$J$5,電機廠報告與驗收規範!$L66,IF(AND(電機廠報告與驗收規範!$N65>電機廠報告與驗收規範!$N66,電機廠報告與驗收規範!$N65=電機廠報告與驗收規範!$J$5),電機廠報告與驗收規範!$L65,電機廠報告與驗收規範!$L64))) -> 6000 | F71: =IF(IF(電機廠報告與驗收規範!$N66=電機廠報告與驗收規範!$J$5,電機廠報告與驗收規範!$L66,IF(AND(電機廠報告與驗收規範!$N65>電機廠報告與驗收規範!$N66,電機廠報告與驗收規範!$N65=電機廠報告與驗收規範!$J$5),電機廠報告與驗收規範!$L65,電機廠報告與驗收規範!$L64))>電機廠報告與驗收規範!$H$5,電機廠報告與驗收規範!$Q$65,IF(IF(電機廠報告與驗收規範!$N65=電機廠報告與驗收規範!$J$5,電機廠報告與驗收規範!$L65,IF(AND(電機廠報告與驗收規範!$N64>電機廠報告與驗收規範!$N65,電機廠報告與驗收規範!$N64=電機廠報告與驗收規範!$J$5),電機廠報告與驗收規範!$L64,電機廠報告與驗收規範!$L63))=電機廠報告與驗收規範!$L63,電機廠報告與驗收規範!$Q64,IF(IF(電機廠報告與驗收規範!$N65=電機廠報告與驗收規範!$J$5,電機廠報告與驗收規範!$L65,IF(AND(電機廠報告與驗收規範!$N64>電機廠報告與驗收規範!$N65,電機廠報告與驗收規範!$N64=電機廠報告與驗收規範!$J$5),電機廠報告與驗收規範!$L64,電機廠報告與驗收規範!$L63))=電機廠報告與驗收規範!$L62,電機廠報告與驗收規範!$Q63,電機廠報告與驗收規範!$Q62))) -> 0 | H71: =IF(IF(電機廠報告與驗收規範!$N66=電機廠報告與驗收規範!$J$5,電機廠報告與驗收規範!$L66,IF(AND(電機廠報告與驗收規範!$N65>電機廠報告與驗收規範!$N66,電機廠報告與驗收規範!$N65=電機廠報告與驗收規範!$J$5),電機廠報告與驗收規範!$L65,電機廠報告與驗收規範!$L64))>電機廠報告與驗收規範!$H$5,電機廠報告與驗收規範!$N$65,IF(IF(電機廠報告與驗收規範!$N65=電機廠報告與驗收規範!$J$5,電機廠報告與驗收規範!$L65,IF(AND(電機廠報告與驗收規範!$N64>電機廠報告與驗收規範!$N65,電機廠報告與驗收規範!$N64=電機廠報告與驗收規範!$J$5),電機廠報告與驗收規範!$L64,電機廠報告與驗收規範!$L63))=電機廠報告與驗收規範!$L63,電機廠報告與驗收規範!$N64,IF(IF(電機廠報告與驗收規範!$N65=電機廠報告與驗收規範!$J$5,電機廠報告與驗收規範!$L65,IF(AND(電機廠報告與驗收規範!$N64>電機廠報告與驗收規範!$N65,電機廠報告與驗收規範!$N64=電機廠報告與驗收規範!$J$5),電機廠報告與驗收規範!$L64,電機廠報告與驗收規範!$L63))=電機廠報告與驗收規範!$L62,電機廠報告與驗收規範!$N63,電機廠報告與驗收規範!$N62))) -> 35 | J71: =IF(IF(電機廠報告與驗收規範!$N66=電機廠報告與驗收規範!$J$5,電機廠報告與驗收規範!$L66,IF(AND(電機廠報告與驗收規範!$N65>電機廠報告與驗收規範!$N66,電機廠報告與驗收規範!$N65=電機廠報告與驗收規範!$J$5),電機廠報告與驗收規範!$L65,電機廠報告與驗收規範!$L64))>電機廠報告與驗收規範!$H$5,電機廠報告與驗收規範!$U$65,IF(IF(電機廠報告與驗收規範!$N65=電機廠報告與驗收規範!$J$5,電機廠報告與驗收規範!$L65,IF(AND(電機廠報告與驗收規範!$N64>電機廠報告與驗收規範!$N65,電機廠報告與驗收規範!$N64=電機廠報告與驗收規範!$J$5),電機廠報告與驗收規範!$L64,電機廠報告與驗收規範!$L63))=電機廠報告與驗收規範!$L63,電機廠報告與驗收規範!$U64,IF(IF(電機廠報告與驗收規範!$N65=電機廠報告與驗收規範!$J$5,電機廠報告與驗收規範!$L65,IF(AND(電機廠報告與驗收規範!$N64>電機廠報告與驗收規範!$N65,電機廠報告與驗收規範!$N64=電機廠報告與驗收規範!$J$5),電機廠報告與驗收規範!$L64,電機廠報告與驗收規範!$L63))=電機廠報告與驗收規範!$L62,電機廠報告與驗收規範!$U63,電機廠報告與驗收規範!$U62))) -> 0 | L71: =ROUND(2*PI()*D71*H71/60/1000,2) -> 21.99
D72: =IF(IF(電機廠報告與驗收規範!$N67=電機廠報告與驗收規範!$J$5,電機廠報告與驗收規範!$L67,IF(AND(電機廠報告與驗收規範!$N66>電機廠報告與驗收規範!$N67,電機廠報告與驗收規範!$N66=電機廠報告與驗收規範!$J$5),電機廠報告與驗收規範!$L66,電機廠報告與驗收規範!$L65))>電機廠報告與驗收規範!$H$5,電機廠報告與驗收規範!$H$5,IF(電機廠報告與驗收規範!$N67=電機廠報告與驗收規範!$J$5,電機廠報告與驗收規範!$L67,IF(AND(電機廠報告與驗收規範!$N66>電機廠報告與驗收規範!$N67,電機廠報告與驗收規範!$N66=電機廠報告與驗收規範!$J$5),電機廠報告與驗收規範!$L66,電機廠報告與驗收規範!$L65))) -> 8000 | F72: =IF(IF(電機廠報告與驗收規範!$N67=電機廠報告與驗收規範!$J$5,電機廠報告與驗收規範!$L67,IF(AND(電機廠報告與驗收規範!$N66>電機廠報告與驗收規範!$N67,電機廠報告與驗收規範!$N66=電機廠報告與驗收規範!$J$5),電機廠報告與驗收規範!$L66,電機廠報告與驗收規範!$L65))>電機廠報告與驗收規範!$H$5,電機廠報告與驗收規範!$Q$65,IF(IF(電機廠報告與驗收規範!$N66=電機廠報告與驗收規範!$J$5,電機廠報告與驗收規範!$L66,IF(AND(電機廠報告與驗收規範!$N65>電機廠報告與驗收規範!$N66,電機廠報告與驗收規範!$N65=電機廠報告與驗收規範!$J$5),電機廠報告與驗收規範!$L65,電機廠報告與驗收規範!$L64))=電機廠報告與驗收規範!$L64,電機廠報告與驗收規範!$Q65,IF(IF(電機廠報告與驗收規範!$N66=電機廠報告與驗收規範!$J$5,電機廠報告與驗收規範!$L66,IF(AND(電機廠報告與驗收規範!$N65>電機廠報告與驗收規範!$N66,電機廠報告與驗收規範!$N65=電機廠報告與驗收規範!$J$5),電機廠報告與驗收規範!$L65,電機廠報告與驗收規範!$L64))=電機廠報告與驗收規範!$L63,電機廠報告與驗收規範!$Q64,電機廠報告與驗收規範!$Q63))) -> 0 | H72: =IF(IF(電機廠報告與驗收規範!$N67=電機廠報告與驗收規範!$J$5,電機廠報告與驗收規範!$L67,IF(AND(電機廠報告與驗收規範!$N66>電機廠報告與驗收規範!$N67,電機廠報告與驗收規範!$N66=電機廠報告與驗收規範!$J$5),電機廠報告與驗收規範!$L66,電機廠報告與驗收規範!$L65))>電機廠報告與驗收規範!$H$5,電機廠報告與驗收規範!$N$65,IF(IF(電機廠報告與驗收規範!$N66=電機廠報告與驗收規範!$J$5,電機廠報告與驗收規範!$L66,IF(AND(電機廠報告與驗收規範!$N65>電機廠報告與驗收規範!$N66,電機廠報告與驗收規範!$N65=電機廠報告與驗收規範!$J$5),電機廠報告與驗收規範!$L65,電機廠報告與驗收規範!$L64))=電機廠報告與驗收規範!$L64,電機廠報告與驗收規範!$N65,IF(IF(電機廠報告與驗收規範!$N66=電機廠報告與驗收規範!$J$5,電機廠報告與驗收規範!$L66,IF(AND(電機廠報告與驗收規範!$N65>電機廠報告與驗收規範!$N66,電機廠報告與驗收規範!$N65=電機廠報告與驗收規範!$J$5),電機廠報告與驗收規範!$L65,電機廠報告與驗收規範!$L64))=電機廠報告與驗收規範!$L63,電機廠報告與驗收規範!$N64,電機廠報告與驗收規範!$N63))) -> 26.25 | J72: =IF(IF(電機廠報告與驗收規範!$N67=電機廠報告與驗收規範!$J$5,電機廠報告與驗收規範!$L67,IF(AND(電機廠報告與驗收規範!$N66>電機廠報告與驗收規範!$N67,電機廠報告與驗收規範!$N66=電機廠報告與驗收規範!$J$5),電機廠報告與驗收規範!$L66,電機廠報告與驗收規範!$L65))>電機廠報告與驗收規範!$H$5,電機廠報告與驗收規範!$U$65,IF(IF(電機廠報告與驗收規範!$N66=電機廠報告與驗收規範!$J$5,電機廠報告與驗收規範!$L66,IF(AND(電機廠報告與驗收規範!$N65>電機廠報告與驗收規範!$N66,電機廠報告與驗收規範!$N65=電機廠報告與驗收規範!$J$5),電機廠報告與驗收規範!$L65,電機廠報告與驗收規範!$L64))=電機廠報告與驗收規範!$L64,電機廠報告與驗收規範!$U65,IF(IF(電機廠報告與驗收規範!$N66=電機廠報告與驗收規範!$J$5,電機廠報告與驗收規範!$L66,IF(AND(電機廠報告與驗收規範!$N65>電機廠報告與驗收規範!$N66,電機廠報告與驗收規範!$N65=電機廠報告與驗收規範!$J$5),電機廠報告與驗收規範!$L65,電機廠報告與驗收規範!$L64))=電機廠報告與驗收規範!$L63,電機廠報告與驗收規範!$U64,電機廠報告與驗收規範!$U63))) -> 0 | L72: =ROUND(2*PI()*D72*H72/60/1000,2) -> 21.99

Sheet 自動審查
A1: 步驟 | B1: 測試項目 | C1: 測試方式 | O1: 繞組電阻測試 | P1: 與平均值誤差容許值 | Q1: 0.05
C2: 使用低阻計量測U-V，V-W，U-W線電阻 | D2: =電機廠報告與驗收規範!J13 -> 參數來源 | E2: =電機廠報告與驗收規範!J15 -> 規格書(設計值) | F2: =電機廠報告與驗收規範!J14 -> 量測數值 | G2: 與平均值誤差(%) | H2: 是否符合 | I2: 未通過原因 | J2: 與設計值誤差(%) | K2: 是否符合 | L2: 未通過原因 | P2: 與設計值誤差容許值 | Q2: 0.05
A3: =電機廠報告與驗收規範!C13 -> 3 | B3: =電機廠報告與驗收規範!D13 -> 繞組電阻測試 | O3: S1 100%負載連續使用測試 | P3: 轉速誤差容許值(非額定轉速) | Q3: 0.03
D4: =電機廠報告與驗收規範!L13 -> Ru-v(Ω) | E4: =電機廠報告與驗收規範!L15 -> 0.27 | F4: =電機廠報告與驗收規範!L14 -> 0.27 | G4: =(F4-$F$7)/$F$7 -> 0 | H4: =IF(ABS(G4)<$Q$1,"Yes","No") -> Yes | I4: =IF(H4="No",_xlfn.TEXTJOIN("",TRUE,"線電阻與平均值誤差>",$Q$1*100,"%"),"") | P4: 轉速誤差容許值(額定轉速) | Q4: 5
D5: =電機廠報告與驗收規範!M13 -> Rv-w(Ω) | E5: =電機廠報告與驗收規範!M15 -> 0.27 | F5: =電機廠報告與驗收規範!M14 -> 0.27 | G5: =(F5-$F$7)/$F$7 -> 0 | H5: =IF(ABS(G5)<$Q$1,"Yes","No") -> Yes | I5: =IF(H5="No",_xlfn.TEXTJOIN("",TRUE,"線電阻與平均值誤差>",$Q$1*100,"%"),"") | P5: 轉矩誤差容許值(非額定轉速) | Q5: 0.03
D6: =電機廠報告與驗收規範!N13 -> Ru-w(Ω) | E6: =電機廠報告與驗收規範!N15 -> 0.27 | F6: =電機廠報告與驗收規範!N14 -> 0.27 | G6: =(F6-$F$7)/$F$7 -> 0 | H6: =IF(ABS(G6)<$Q$1,"Yes","No") -> Yes | I6: =IF(H6="No",_xlfn.TEXTJOIN("",TRUE,"線電阻與平均值誤差>",$Q$1*100,"%"),"") | P6: 轉矩誤差容許值(額定轉速) | Q6: 0.01
D7: =電機廠報告與驗收規範!O13 -> Ravg (Ω) | E7: =電機廠報告與驗收規範!O15 -> 0.27 | F7: =電機廠報告與驗收規範!O14 -> 0.27 | J7: =電機廠報告與驗收規範!O16 -> 0 | K7: =IF(ABS(J7)<Q2,"Yes","No") -> Yes | L7: =IF(K7="No",_xlfn.TEXTJOIN("",TRUE,"電阻量測平均值與設計值誤差>",$Q$2*100,"%"),"") | P7: 輸入功率誤差容許值 | Q7: 0.05
A8: =電機廠報告與驗收規範!C31 -> 10 | B8: =電機廠報告與驗收規範!D31 -> S1 100%負載連續使用測試 | C8: 電機於溫升測試達熱穩態後後進行T-N與P-N曲線測試。 參考以下紀錄負載T-N與P-N曲線測試數據 初始轉速: 50%額定轉速測試 轉速間隔: 50%額定轉速 最終轉速:電機最高轉速規格 最終扭力: 該轉速對應T-N曲線規格最大扭力 以"量測轉速"等於"目標轉速"的情況下進行測試，加大扭力會增加滑差、使"量測轉速"降低，請再提高轉速命令(同步頻率)，使"量測轉速"等於"目標轉速"，再紀錄測試結果 如果因實驗設備限制，請註明可以實測的轉矩與速度的範圍；並且提供建議的測試操作點。(請電機廠備註使用的驅動器) 無法提供的數據請備註原因, 並填上N/A 其餘細節參考表格下方備註 | D8: 目標轉速(%) | E8: 目標轉速(RPM) | F8: 量測轉速(RPM) | G8: 轉速誤差 (% or rpm) | H8: 是否符合 | I8: 未通過原因 | P8: 輸出功率誤差容許值 | Q8: 0.05
P9: 電壓誤差容許值(非額定轉速) | Q9: 0.05
D10: =電機廠報告與驗收規範!$J$33 -> 0.5 | E10: =電機廠報告與驗收規範!$J$3*D10 -> 750 | F10: =IF(電機廠報告與驗收規範!N33="","-",電機廠報告與驗收規範!N33) -> 749 | G10: =IF(F10<>"-",(F10-E10)/E10,"-") -> -0.0013333333 | H10: {=_xlfn.IFS(G10="-","-",ABS(G10)<=$Q$3,"Yes",TRUE,"No")} -> #NAME? | I10: =IF(H10="No",_xlfn.TEXTJOIN("",TRUE,"轉速誤差>",$Q$3*100,"%"),"") -> #NAME? | P10: 電壓誤差容許值(額定轉速) | Q10: 0.03
D11: =電機廠報告與驗收規範!$J$34 -> 1 | E11: =電機廠報告與驗收規範!$J$3*D11 -> 1500 | F11: =IF(電機廠報告與驗收規範!N34="","-",電機廠報告與驗收規範!N34) -> 1502 | G11: =IF(F11<>"-",F11-E11,"-") -> 2 | H11: {=_xlfn.IFS(G11="-","-",ABS(G11)<=$Q$4,"Yes",TRUE,"No")} -> #NAME? | I11: =IF(H11="No",_xlfn.TEXTJOIN("",TRUE,"轉速誤差>",Q4,"rpm"),"") -> #NAME? | P11: 電流誤差容許值(非額定轉速) | Q11: 0.05
D12: =電機廠報告與驗收規範!$J$35 -> 1.5 | E12: =電機廠報告與驗收規範!$J$3*D12 -> 2250 | F12: =IF(電機廠報告與驗收規範!N35="","-",電機廠報告與驗收規範!N35) -> - | G12: =IF(F12<>"-",(F12-E12)/E12,"-") -> - | H12: {=_xlfn.IFS(G12="-","-",ABS(G12)<=$Q$3,"Yes",TRUE,"No")} -> #NAME? | I12: =IF(H12="No",_xlfn.TEXTJOIN("",TRUE,"轉速誤差>",$Q$3*100,"%"),"") -> #NAME? | P12: 電流誤差容許值(額定轉速) | Q12: 0.03
D13: =電機廠報告與驗收規範!$J$36 -> 2 | E13: =電機廠報告與驗收規範!$J$3*D13 -> 3000 | F13: =IF(電機廠報告與驗收規範!N36="","-",電機廠報告與驗收規範!N36) -> - | G13: =IF(F13<>"-",(F13-E13)/E13,"-") -> - | H13: {=_xlfn.IFS(G13="-","-",ABS(G13)<=$Q$3,"Yes",TRUE,"No")} -> #NAME? | I13: =IF(H13="No",_xlfn.TEXTJOIN("",TRUE,"轉速誤差>",$Q$3*100,"%"),"") -> #NAME? | P13: 三相電壓誤差容許值 | Q13: 0.03
D14: =電機廠報告與驗收規範!$J$37 -> 2.5 | E14: =電機廠報告與驗收規範!$J$3*D14 -> 3750 | F14: =IF(電機廠報告與驗收規範!N37="","-",電機廠報告與驗收規範!N37) -> - | G14: =IF(F14<>"-",(F14-E14)/E14,"-") -> - | H14: {=_xlfn.IFS(G14="-","-",ABS(G14)<=$Q$3,"Yes",TRUE,"No")} -> #NAME? | I14: =IF(H14="No",_xlfn.TEXTJOIN("",TRUE,"轉速誤差>",$Q$3*100,"%"),"") -> #NAME? | P14: 三相電流誤差容許值 | Q14: 0.05
D15: =電機廠報告與驗收規範!$J$38 -> 3 | E15: =電機廠報告與驗收規範!$J$3*D15 -> 4500 | F15: =IF(電機廠報告與驗收規範!N38="","-",電機廠報告與驗收規範!N38) -> - | G15: =IF(F15<>"-",(F15-E15)/E15,"-") -> - | H15: {=_xlfn.IFS(G15="-","-",ABS(G15)<=$Q$3,"Yes",TRUE,"No")} -> #NAME? | I15: =IF(H15="No",_xlfn.TEXTJOIN("",TRUE,"轉速誤差>",$Q$3*100,"%"),"") -> #NAME? | O15: S2 短時間使用150%負載測試 | P15: 轉速誤差容許值 | Q15: 0.05
D16: =電機廠報告與驗收規範!$J$39 -> 3.5 | E16: =電機廠報告與驗收規範!$J$3*D16 -> 5250 | F16: =IF(電機廠報告與驗收規範!N39="","-",電機廠報告與驗收規範!N39) -> - | G16: =IF(F16<>"-",(F16-E16)/E16,"-") -> - | H16: {=_xlfn.IFS(G16="-","-",ABS(G16)<=$Q$3,"Yes",TRUE,"No")} -> #NAME? | I16: =IF(H16="No",_xlfn.TEXTJOIN("",TRUE,"轉速誤差>",$Q$3*100,"%"),"") -> #NAME? | P16: 轉矩誤差容許值 | Q16: 0.05
D17: =電機廠報告與驗收規範!$J$40 -> 4 | E17: =電機廠報告與驗收規範!$J$3*D17 -> 6000 | F17: =IF(電機廠報告與驗收規範!N40="","-",電機廠報告與驗收規範!N40) -> - | G17: =IF(F17<>"-",(F17-E17)/E17,"-") -> - | H17: {=_xlfn.IFS(G17="-","-",ABS(G17)<=$Q$3,"Yes",TRUE,"No")} -> #NAME? | I17: =IF(H17="No",_xlfn.TEXTJOIN("",TRUE,"轉速誤差>",$Q$3*100,"%"),"") -> #NAME? | P17: 輸入功率誤差容許值 | Q17: 0.05
D18: =電機廠報告與驗收規範!$J$41 -> 最高轉速 | E18: =電機廠報告與驗收規範!H5 -> 8000 | F18: =IF(電機廠報告與驗收規範!N41="","-",電機廠報告與驗收規範!N41) -> - | G18: =IF(F18<>"-",(F18-E18)/E18,"-") -> - | H18: {=_xlfn.IFS(G18="-","-",ABS(G18)<=$Q$3,"Yes",TRUE,"No")} -> #NAME? | I18: =IF(H18="No",_xlfn.TEXTJOIN("",TRUE,"轉速誤差>",$Q$3*100,"%"),"") -> #NAME? | P18: 輸出功率誤差容許值 | Q18: 0.05
D19: 目標轉速(%) | E19: 轉矩設定(%) | F19: 轉矩設定(Nm) | G19: 量測轉矩(Nm) | H19: 轉矩誤差 (%) | I19: 是否符合 | J19: 未通過原因 | P19: 電壓誤差容許值 | Q19: 0.05
P20: 三相電壓誤差容許值 | Q20: 0.03
D21: =電機廠報告與驗收規範!$J$33 -> 0.5 | E21: =電機廠報告與驗收規範!L33 -> 1 | F21: =電機廠報告與驗收規範!M33 -> 70 | G21: =IF(電機廠報告與驗收規範!P33="","-",電機廠報告與驗收規範!P33) -> 70.14 | H21: =IF(G21<>"-",(G21-F21)/F21,"-") -> 0.002 | I21: {=_xlfn.IFS(H21="-","-",ABS(H21)<=$Q$5,"Yes",TRUE,"No")} -> #NAME? | J21: =IF(I21="No",_xlfn.TEXTJOIN("",TRUE,"轉矩誤差>",$Q$5*100,"%"),"") -> #NAME? | P21: 三相電流誤差容許值 | Q21: 0.05
D22: =電機廠報告與驗收規範!$J$34 -> 1 | E22: =電機廠報告與驗收規範!L34 -> 1 | F22: =電機廠報告與驗收規範!M34 -> 70 | G22: =IF(電機廠報告與驗收規範!P34="","-",電機廠報告與驗收規範!P34) -> 69.36 | H22: =IF(G22<>"-",(G22-F22)/F22,"-") -> -0.0091428571 | I22: {=_xlfn.IFS(H22="-","-",ABS(H22)<=$Q$5,"Yes",TRUE,"No")} -> #NAME? | J22: =IF(I22="No",_xlfn.TEXTJOIN("",TRUE,"轉矩誤差>",$Q$6*100,"%"),"") -> #NAME? | O22: S3 / S6 反覆使用測試 | P22: 轉速誤差容許值 | Q22: 0.05
D23: =電機廠報告與驗收規範!$J$35 -> 1.5 | E23: =電機廠報告與驗收規範!L35 -> 0.66666667 | F23: =電機廠報告與驗收規範!M35 -> 46.666667 | G23: =IF(電機廠報告與驗收規範!P35="","-",電機廠報告與驗收規範!P35) -> - | H23: =IF(G23<>"-",(G23-F23)/F23,"-") -> - | I23: {=_xlfn.IFS(H23="-","-",ABS(H23)<=$Q$5,"Yes",TRUE,"No")} -> #NAME? | J23: =IF(I23="No",_xlfn.TEXTJOIN("",TRUE,"轉矩誤差>",$Q$5*100,"%"),"") -> #NAME? | P23: 轉矩誤差容許值 | Q23: 0.05
D24: =電機廠報告與驗收規範!$J$36 -> 2 | E24: =電機廠報告與驗收規範!L36 -> 0.5 | F24: =電機廠報告與驗收規範!M36 -> 35 | G24: =IF(電機廠報告與驗收規範!P36="","-",電機廠報告與驗收規範!P36) -> - | H24: =IF(G24<>"-",(G24-F24)/F24,"-") -> - | I24: {=_xlfn.IFS(H24="-","-",ABS(H24)<=$Q$5,"Yes",TRUE,"No")} -> #NAME? | J24: =IF(I24="No",_xlfn.TEXTJOIN("",TRUE,"轉矩誤差>",$Q$5*100,"%"),"") -> #NAME? | P24: 三相電流誤差容許值 | Q24: 0.05
D25: =電機廠報告與驗收規範!$J$37 -> 2.5 | E25: =電機廠報告與驗收規範!L37 -> 0.4 | F25: =電機廠報告與驗收規範!M37 -> 28 | G25: =IF(電機廠報告與驗收規範!P37="","-",電機廠報告與驗收規範!P37) -> - | H25: =IF(G25<>"-",(G25-F25)/F25,"-") -> - | I25: {=_xlfn.IFS(H25="-","-",ABS(H25)<=$Q$5,"Yes",TRUE,"No")} -> #NAME? | J25: =IF(I25="No",_xlfn.TEXTJOIN("",TRUE,"轉矩誤差>",$Q$5*100,"%"),"") -> #NAME? | O25: 提供等校參數(實測值) | P25: R1與各項電阻平均的誤差容許值 | Q25: 0.03
D26: =電機廠報告與驗收規範!$J$38 -> 3 | E26: =電機廠報告與驗收規範!L38 -> 0.33333333 | F26: =電機廠報告與驗收規範!M38 -> 23.333333 | G26: =IF(電機廠報告與驗收規範!P38="","-",電機廠報告與驗收規範!P38) -> - | H26: =IF(G26<>"-",(G26-F26)/F26,"-") -> - | I26: {=_xlfn.IFS(H26="-","-",ABS(H26)<=$Q$5,"Yes",TRUE,"No")} -> #NAME? | J26: =IF(I26="No",_xlfn.TEXTJOIN("",TRUE,"轉矩誤差>",$Q$5*100,"%"),"") -> #NAME?
D27: =電機廠報告與驗收規範!$J$39 -> 3.5 | E27: =電機廠報告與驗收規範!L39 -> 0.28571429 | F27: =電機廠報告與驗收規範!M39 -> 20 | G27: =IF(電機廠報告與驗收規範!P39="","-",電機廠報告與驗收規範!P39) -> - | H27: =IF(G27<>"-",(G27-F27)/F27,"-") -> - | I27: {=_xlfn.IFS(H27="-","-",ABS(H27)<=$Q$5,"Yes",TRUE,"No")} -> #NAME? | J27: =IF(I27="No",_xlfn.TEXTJOIN("",TRUE,"轉矩誤差>",$Q$5*100,"%"),"") -> #NAME?
D28: =電機廠報告與驗收規範!$J$40 -> 4 | E28: =電機廠報告與驗收規範!L40 -> 0.25 | F28: =電機廠報告與驗收規範!M40 -> 17.5 | G28: =IF(電機廠報告與驗收規範!P40="","-",電機廠報告與驗收規範!P40) -> - | H28: =IF(G28<>"-",(G28-F28)/F28,"-") -> - | I28: {=_xlfn.IFS(H28="-","-",ABS(H28)<=$Q$5,"Yes",TRUE,"No")} -> #NAME? | J28: =IF(I28="No",_xlfn.TEXTJOIN("",TRUE,"轉矩誤差>",$Q$5*100,"%"),"") -> #NAME?
D29: =電機廠報告與驗收規範!$J$41 -> 最高轉速 | E29: =電機廠報告與驗收規範!L41 -> 0.1875 | F29: =電機廠報告與驗收規範!M41 -> 13.125 | G29: =IF(電機廠報告與驗收規範!P41="","-",電機廠報告與驗收規範!P41) -> - | H29: =IF(G29<>"-",(G29-F29)/F29,"-") -> - | I29: {=_xlfn.IFS(H29="-","-",ABS(H29)<=$Q$5,"Yes",TRUE,"No")} -> #NAME? | J29: =IF(I29="No",_xlfn.TEXTJOIN("",TRUE,"轉矩誤差>",$Q$5*100,"%"),"") -> #NAME?
D30: 目標轉速(%) | E30: 線電壓1(Vrms) | F30: 線電壓2(Vrms) | G30: 線電壓3(Vrms) | H30: 平均電壓誤差(%) | I30: 是否符合 | J30: 未通過原因 | K30: 三相電壓誤差(%) | L30: 是否符合 | M30: 未通過原因
D32: =電機廠報告與驗收規範!$J$33 -> 0.5 | E32: =IF(電機廠報告與驗收規範!Q33="","-",電機廠報告與驗收規範!Q33) -> 134.1 | F32: =IF(電機廠報告與驗收規範!R33="","-",電機廠報告與驗收規範!R33) -> 134.2 | G32: =IF(電機廠報告與驗收規範!S33="","-",電機廠報告與驗收規範!S33) -> 134..1 | K32: =IF(E32<>"-",(MAX(E32:G32)-MIN(E32:G32))/MIN(E32:G32),"-") -> 0.00074571216 | L32: {=_xlfn.IFS(K32="-","-",K32<=$Q$13,"Yes",TRUE,"No")} -> #NAME? | M32: =IF(L32="No",_xlfn.TEXTJOIN("",TRUE,"三相電壓誤差>",$Q$13*100,"%"),"") -> #NAME?
D33: =電機廠報告與驗收規範!$J$34 -> 1 | E33: =IF(電機廠報告與驗收規範!Q34="","-",電機廠報告與驗收規範!Q34) -> 257.5 | F33: =IF(電機廠報告與驗收規範!R34="","-",電機廠報告與驗收規範!R34) -> 257.5 | G33: =IF(電機廠報告與驗收規範!S34="","-",電機廠報告與驗收規範!S34) -> 257.7 | H33: =IF(E33<>"-",(AVERAGE(E33:G33)-電機廠報告與驗收規範!$H$3)/電機廠報告與驗收規範!$H$3,"-") -> -0.0093589744 | I33: {=_xlfn.IFS(H33="-","-",ABS(H33)<=$Q$10,"Yes",TRUE,"No")} -> #NAME? | J33: =IF(I33="No",_xlfn.TEXTJOIN("",TRUE,"平均電壓誤差>",$Q$10*100,"%"),"") -> #NAME? | K33: =IF(E33<>"-",(MAX(E33:G33)-MIN(E33:G33))/MIN(E33:G33),"-") -> 0.00077669903 | L33: {=_xlfn.IFS(K33="-","-",K33<=$Q$13,"Yes",TRUE,"No")} -> #NAME? | M33: =IF(L33="No",_xlfn.TEXTJOIN("",TRUE,"三相電壓誤差>",$Q$13*100,"%"),"") -> #NAME?
D34: =電機廠報告與驗收規範!$J$35 -> 1.5 | E34: =IF(電機廠報告與驗收規範!Q35="","-",電機廠報告與驗收規範!Q35) -> - | F34: =IF(電機廠報告與驗收規範!R35="","-",電機廠報告與驗收規範!R35) -> - | G34: =IF(電機廠報告與驗收規範!S35="","-",電機廠報告與驗收規範!S35) -> - | H34: =IF(E34<>"-",(AVERAGE(E34:G34)-電機廠報告與驗收規範!$H$3)/電機廠報告與驗收規範!$H$3,"-") -> - | I34: {=_xlfn.IFS(H34="-","-",ABS(H34)<=$Q$10,"Yes",TRUE,"No")} -> #NAME? | J34: =IF(I34="No",_xlfn.TEXTJOIN("",TRUE,"平均電壓誤差>",$Q$9*100,"%"),"") -> #NAME? | K34: =IF(E34<>"-",(MAX(E34:G34)-MIN(E34:G34))/MIN(E34:G34),"-") -> - | L34: {=_xlfn.IFS(K34="-","-",K34<=$Q$13,"Yes",TRUE,"No")} -> #NAME? | M34: =IF(L34="No",_xlfn.TEXTJOIN("",TRUE,"三相電壓誤差>",$Q$13*100,"%"),"") -> #NAME?
D35: =電機廠報告與驗收規範!$J$36 -> 2 | E35: =IF(電機廠報告與驗收規範!Q36="","-",電機廠報告與驗收規範!Q36) -> - | F35: =IF(電機廠報告與驗收規範!R36="","-",電機廠報告與驗收規範!R36) -> - | G35: =IF(電機廠報告與驗收規範!S36="","-",電機廠報告與驗收規範!S36) -> - | H35: =IF(E35<>"-",(AVERAGE(E35:G35)-電機廠報告與驗收規範!$H$3)/電機廠報告與驗收規範!$H$3,"-") -> - | I35: {=_xlfn.IFS(H35="-","-",ABS(H35)<=$Q$10,"Yes",TRUE,"No")} -> #NAME? | J35: =IF(I35="No",_xlfn.TEXTJOIN("",TRUE,"平均電壓誤差>",$Q$9*100,"%"),"") -> #NAME? | K35: =IF(E35<>"-",(MAX(E35:G35)-MIN(E35:G35))/MIN(E35:G35),"-") -> - | L35: {=_xlfn.IFS(K35="-","-",K35<=$Q$13,"Yes",TRUE,"No")} -> #NAME? | M35: =IF(L35="No",_xlfn.TEXTJOIN("",TRUE,"三相電壓誤差>",$Q$13*100,"%"),"") -> #NAME?
D36: =電機廠報告與驗收規範!$J$37 -> 2.5 | E36: =IF(電機廠報告與驗收規範!Q37="","-",電機廠報告與驗收規範!Q37) -> - | F36: =IF(電機廠報告與驗收規範!R37="","-",電機廠報告與驗收規範!R37) -> - | G36: =IF(電機廠報告與驗收規範!S37="","-",電機廠報告與驗收規範!S37) -> - | H36: =IF(E36<>"-",(AVERAGE(E36:G36)-電機廠報告與驗收規範!$H$3)/電機廠報告與驗收規範!$H$3,"-") -> - | I36: {=_xlfn.IFS(H36="-","-",ABS(H36)<=$Q$10,"Yes",TRUE,"No")} -> #NAME? | J36: =IF(I36="No",_xlfn.TEXTJOIN("",TRUE,"平均電壓誤差>",$Q$9*100,"%"),"") -> #NAME? | K36: =IF(E36<>"-",(MAX(E36:G36)-MIN(E36:G36))/MIN(E36:G36),"-") -> - | L36: {=_xlfn.IFS(K36="-","-",K36<=$Q$13,"Yes",TRUE,"No")} -> #NAME? | M36: =IF(L36="No",_xlfn.TEXTJOIN("",TRUE,"三相電壓誤差>",$Q$13*100,"%"),"") -> #NAME?
D37: =電機廠報告與驗收規範!$J$38 -> 3 | E37: =IF(電機廠報告與驗收規範!Q38="","-",電機廠報告與驗收規範!Q38) -> - | F37: =IF(電機廠報告與驗收規範!R38="","-",電機廠報告與驗收規範!R38) -> - | G37: =IF(電機廠報告與驗收規範!S38="","-",電機廠報告與驗收規範!S38) -> - | H37: =IF(E37<>"-",(AVERAGE(E37:G37)-電機廠報告與驗收規範!$H$3)/電機廠報告與驗收規範!$H$3,"-") -> - | I37: {=_xlfn.IFS(H37="-","-",ABS(H37)<=$Q$10,"Yes",TRUE,"No")} -> #NAME? | J37: =IF(I37="No",_xlfn.TEXTJOIN("",TRUE,"平均電壓誤差>",$Q$9*100,"%"),"") -> #NAME? | K37: =IF(E37<>"-",(MAX(E37:G37)-MIN(E37:G37))/MIN(E37:G37),"-") -> - | L37: {=_xlfn.IFS(K37="-","-",K37<=$Q$13,"Yes",TRUE,"No")} -> #NAME? | M37: =IF(L37="No",_xlfn.TEXTJOIN("",TRUE,"三相電壓誤差>",$Q$13*100,"%"),"") -> #NAME?
D38: =電機廠報告與驗收規範!$J$39 -> 3.5 | E38: =IF(電機廠報告與驗收規範!Q39="","-",電機廠報告與驗收規範!Q39) -> - | F38: =IF(電機廠報告與驗收規範!R39="","-",電機廠報告與驗收規範!R39) -> - | G38: =IF(電機廠報告與驗收規範!S39="","-",電機廠報告與驗收規範!S39) -> - | H38: =IF(E38<>"-",(AVERAGE(E38:G38)-電機廠報告與驗收規範!$H$3)/電機廠報告與驗收規範!$H$3,"-") -> - | I38: {=_xlfn.IFS(H38="-","-",ABS(H38)<=$Q$10,"Yes",TRUE,"No")} -> #NAME? | J38: =IF(I38="No",_xlfn.TEXTJOIN("",TRUE,"平均電壓誤差>",$Q$9*100,"%"),"") -> #NAME? | K38: =IF(E38<>"-",(MAX(E38:G38)-MIN(E38:G38))/MIN(E38:G38),"-") -> - | L38: {=_xlfn.IFS(K38="-","-",K38<=$Q$13,"Yes",TRUE,"No")} -> #NAME? | M38: =IF(L38="No",_xlfn.TEXTJOIN("",TRUE,"三相電壓誤差>",$Q$13*100,"%"),"") -> #NAME?
D39: =電機廠報告與驗收規範!$J$40 -> 4 | E39: =IF(電機廠報告與驗收規範!Q40="","-",電機廠報告與驗收規範!Q40) -> - | F39: =IF(電機廠報告與驗收規範!R40="","-",電機廠報告與驗收規範!R40) -> - | G39: =IF(電機廠報告與驗收規範!S40="","-",電機廠報告與驗收規範!S40) -> - | H39: =IF(E39<>"-",(AVERAGE(E39:G39)-電機廠報告與驗收規範!$H$3)/電機廠報告與驗收規範!$H$3,"-") -> - | I39: {=_xlfn.IFS(H39="-","-",ABS(H39)<=$Q$10,"Yes",TRUE,"No")} -> #NAME? | J39: =IF(I39="No",_xlfn.TEXTJOIN("",TRUE,"平均電壓誤差>",$Q$9*100,"%"),"") -> #NAME? | K39: =IF(E39<>"-",(MAX(E39:G39)-MIN(E39:G39))/MIN(E39:G39),"-") -> - | L39: {=_xlfn.IFS(K39="-","-",K39<=$Q$13,"Yes",TRUE,"No")} -> #NAME? | M39: =IF(L39="No",_xlfn.TEXTJOIN("",TRUE,"三相電壓誤差>",$Q$13*100,"%"),"") -> #NAME?
D40: =電機廠報告與驗收規範!$J$41 -> 最高轉速 | E40: =IF(電機廠報告與驗收規範!Q41="","-",電機廠報告與驗收規範!Q41) -> - | F40: =IF(電機廠報告與驗收規範!R41="","-",電機廠報告與驗收規範!R41) -> - | G40: =IF(電機廠報告與驗收規範!S41="","-",電機廠報告與驗收規範!S41) -> - | H40: =IF(E40<>"-",(AVERAGE(E40:G40)-電機廠報告與驗收規範!$H$3)/電機廠報告與驗收規範!$H$3,"-") -> - | I40: {=_xlfn.IFS(H40="-","-",ABS(H40)<=$Q$10,"Yes",TRUE,"No")} -> #NAME? | J40: =IF(I40="No",_xlfn.TEXTJOIN("",TRUE,"平均電壓誤差>",$Q$9*100,"%"),"") -> #NAME? | K40: =IF(E40<>"-",(MAX(E40:G40)-MIN(E40:G40))/MIN(E40:G40),"-") -> - | L40: {=_xlfn.IFS(K40="-","-",K40<=$Q$13,"Yes",TRUE,"No")} -> #NAME? | M40: =IF(L40="No",_xlfn.TEXTJOIN("",TRUE,"三相電壓誤差>",$Q$13*100,"%"),"") -> #NAME?
D41: 目標轉速(%) | E41: 線電流1(Arms) | F41: 線電流2(Arms) | G41: 線電流3(Arms) | H41: 平均電流誤差(%) | I41: 是否符合 | J41: 未通過原因 | K41: 三相電流誤差(%) | L41: 是否符合 | M41: 未通過原因
...

Sheet 相關表格
B4: 水冷進水口溫度降額表 | L4: 水冷進水口流速表
